Workbook

Sheet Payment Entry
A1: Amended From | B1: ID | C1: Series | D1: Payment Type | E1: Posting Date | F1: Company | G1: Account Paid From | H1: Account Currency (From) | I1: Account Paid To | J1: Account Currency (To) | K1: Paid Amount | L1: Source Exchange Rate | M1: Paid Amount (Company Currency) | N1: Received Amount | O1: Target Exchange Rate | P1: Received Amount (Company Currency) | Q1: Workflow State | R1: Payment Order Status | S1: Mode of Payment | T1: Party Type | U1: Party | V1: Party Name | W1: Book Advance Payments in Separate Party Account | X1: Reconcile on Advance Payment Date | Y1: Company Bank Account | Z1: Party Bank Account | AA1: Contact | AB1: Email | AC1: Party Balance | AD1: Paid From Account Type | AE1: Account Balance (From) | AF1: Paid To Account Type | AG1: Account Balance (To) | AH1: Paid Amount After Tax | AI1: Paid Amount After Tax (Company Currency) | AJ1: Received Amount After Tax | AK1: Received Amount After Tax (Company Currency) | AL1: Total Allocated Amount | AM1: Total Allocated Amount (Company Currency) | AN1: Unallocated Amount | AO1: Difference Amount (Company Currency) | AP1: Purchase Taxes and Charges Template | AQ1: Sales Taxes and Charges Template | AR1: Apply Tax Withholding Amount | AS1: Tax Withholding Category | AT1: Total Taxes and Charges (Company Currency) | AU1: Total Taxes and Charges | AV1: Company Address | AW1: Company GSTIN | AX1: Place of Supply | AY1: Customer Address | AZ1: Customer GSTIN | BA1: GST Category | BB1: Cheque/Reference No | BC1: Cheque/Reference Date | BD1: Clearance Date | BE1: Project | BF1: Branch | BG1: Cost Center | BH1: Status | BI1: Custom Remarks | BJ1: Remarks | BK1: In Words (Company Currency) | BL1: Is Opening | BM1: Letter Head | BN1: Print Heading | BO1: Bank | BP1: Bank Account No | BQ1: Payment Order | BR1: In Words | BS1: Auto Repeat | BT1: Title | BU1: ID (Payment References) | BV1: Account (Payment References) | BW1: Account Type (Payment References) | BX1: Allocated (Payment References) | BY1: Due Date (Payment References) | BZ1: Exchange Gain/Loss (Payment References) | CA1: Exchange Rate (Payment References) | CB1: Grand Total (Payment References) | CC1: Name (Payment References) | CD1: Outstanding (Payment References) | CE1: Payment Request (Payment References) | CF1: Payment Term (Payment References) | CG1: Payment Term Outstanding (Payment References) | CH1: Payment Type (Payment References) | CI1: Reconcile Effect On (Payment References) | CJ1: Supplier Invoice No (Payment References) | CK1: Type (Payment References) | CL1: ID (Advance Taxes and Charges) | CM1: Account Currency (Advance Taxes and Charges) | CN1: Account Head (Advance Taxes and Charges) | CO1: Add Or Deduct (Advance Taxes and Charges) | CP1: Allocated Amount (Advance Taxes and Charges) | CQ1: Amount (Advance Taxes and Charges) | CR1: Amount (Company Currency) (Advance Taxes and Charges) | CS1: Considered In Paid Amount (Advance Taxes and Charges) | CT1: Cost Center (Advance Taxes and Charges) | CU1: Description (Advance Taxes and Charges) | CV1: GST Tax Type (Advance Taxes and Charges) | CW1: Reference Row # (Advance Taxes and Charges) | CX1: Tax Rate (Advance Taxes and Charges) | CY1: Total (Advance Taxes and Charges) | CZ1: Total (Company Currency) (Advance Taxes and Charges) | DA1: Type (Advance Taxes and Charges) | DB1: ID (Payment Deductions or Loss) | DC1: Account (Payment Deductions or Loss) | DD1: Amount (Company Currency) (Payment Deductions or Loss) | DE1: Branch (Payment Deductions or Loss) | DF1: Cost Center (Payment Deductions or Loss) | DG1: Description (Payment Deductions or Loss) | DH1: Is Exchange Gain / Loss? (Payment Deductions or Loss)
A2: PAY/G/25-26/1538 | B2: PAY/G/25-26/1538-1 | C2: PAY/G/23-24/.#### | D2: Pay | E2: 45869 | F2: G. C. Foods Pvt. Ltd. | G2: 9210300223943516 - Axis Bank Ltd. CC Tronica - GCF | H2: INR | I2: Creditors - GCF | J2: INR | K2: 87439 | L2: 1 | M2: 87439 | N2: 87439 | O2: 1 | P2: 87439 | Q2: Approved | R2: Initiated | S2: NEFT/RTGS | T2: Supplier | U2: Axis Bank (Term Loan 921060054746668) | V2: Axis Bank (Term Loan 921060054746668) | W2: 0 | X2: 0 | Y2: AXIS BANK 921030023943516 - GZB | AC2: 2135865 | AD2: Bank | AE2: 11209075 | AF2: Payable | AG2: 2135865 | AH2: 87439 | AI2: 87439 | AJ2: 87439 | AK2: 87439 | AL2: 0 | AM2: 0 | AN2: 87439 | AO2: 0 | AR2: 0 | AT2: 0 | AU2: 0 | AV2: G.C. Foods Pvt. Ltd.Ghaziabad - Uttar Pradesh-Billing | AW2: 09AACCG2244H1ZS | BB2: N/A | BC2: 45869 | BF2: Ghaziabad | BH2: Cancelled | BI2: 0 | BJ2: Amount INR 87439.0 to Axis Bank (Term Loan 921060054746668) Transaction reference no N/A dated 2025-07-31 | BK2: INR Eighty Seven Thousand, Four Hundred And Thirty Nine only. | BL2: No | BM2: GCF Letterhead | BO2: AXIS BANK | BP2: 921030023943516 | BR2: INR Eighty Seven Thousand, Four Hundred And Thirty Nine only. | BT2: Axis Bank (Term Loan 921060054746668)
A3: PAY/G/25-26/1537 | B3: PAY/G/25-26/1537-1 | C3: PAY/G/23-24/.#### | D3: Pay | E3: 45759 | F3: G. C. Foods Pvt. Ltd. | G3: 922020051221442 - Axis Bank - GZB - GCF | H3: INR | I3: Creditors - GCF | J3: INR | K3: 40000 | L3: 1 | M3: 40000 | N3: 40000 | O3: 1 | P3: 40000 | Q3: Approved | R3: Initiated | T3: Supplier | U3: Freight Outward Non TDS | V3: Freight Outward Non TDS | W3: 0 | X3: 0 | Y3: AXIS BANK 922020051221442 - GZB | AC3: -43600 | AD3: Bank | AE3: 101269.38 | AF3: Payable | AG3: -43600 | AH3: 40000 | AI3: 40000 | AJ3: 40000 | AK3: 40000 | AL3: 0 | AM3: 0 | AN3: 40000 | AO3: 0 | AR3: 0 | AT3: 0 | AU3: 0 | AV3: G.C. Foods Pvt. Ltd.Ghaziabad - Uttar Pradesh-Billing | AW3: 09AACCG2244H1ZS | BB3: NA | BC3: 45749 | BF3: Ghaziabad | BH3: Cancelled | BI3: 0 | BJ3: Amount INR 40000 to Freight Outward Non TDS Transaction reference no NA dated 2025-04-02 | BK3: INR Forty Thousand only. | BL3: No | BM3: GCF Letterhead | BO3: AXIS BANK | BP3: 922020051221442 | BR3: INR Forty Thousand only. | BT3: Freight Outward Non TDS
A4: PAY/M/25-26/0946 | B4: PAY/M/25-26/0946-1 | C4: PAY/G/23-24/.#### | D4: Receive | E4: 45869 | F4: G. C. Foods Pvt. Ltd. | G4: Debtors - GCF | H4: INR | I4: 9210300223943516 - Axis Bank Ltd. CC Tronica - GCF | J4: INR | K4: 400000 | L4: 1 | M4: 400000 | N4: 400000 | O4: 1 | P4: 400000 | Q4: Approved | R4: Initiated | S4: NEFT/RTGS | T4: Customer | U4: G.C.foods Pvt Ltd (T) | V4: G.C.foods Pvt Ltd (T) | W4: 0 | X4: 0 | Y4: AXIS BANK 921030023943516 - GZB | AC4: -33308502 | AD4: Receivable | AE4: -33308502 | AF4: Bank | AG4: -56190692 | AH4: 400000 | AI4: 400000 | AJ4: 400000 | AK4: 400000 | AL4: 0 | AM4: 0 | AN4: 400000 | AO4: 0 | AR4: 0 | AT4: 0 | AU4: 0 | AV4: GC Foods Muzaffarpur-Billing | AW4: 10AACCG2244H1Z9 | AX4: 09-Uttar Pradesh | AY4: G.C.foods Pvt Ltd (T)-Billing | AZ4: 09AACCG2244H1ZS | BA4: Registered Regular | BB4: N/A | BC4: 45869 | BF4: Muzaffarpur | BH4: Cancelled | BI4: 0 | BJ4: Amount INR 400000 received from G.C.foods Pvt Ltd (T) Transaction reference no N/A dated 2025-07-31 | BK4: INR Four Lakh only. | BL4: No | BM4: GCF Letterhead | BO4: AXIS BANK | BP4: 921030023943516 | BR4: INR Four Lakh only. | BT4: G.C.foods Pvt Ltd (T)
A5: PAY/G/25-26/1502 | B5: PAY/G/25-26/1502-1 | C5: PAY/G/23-24/.#### | D5: Pay | E5: 45867 | F5: G. C. Foods Pvt. Ltd. | G5: 9210300223943516 - Axis Bank Ltd. CC Tronica - GCF | H5: INR | I5: Creditors - GCF | J5: INR | K5: 18195 | L5: 1 | M5: 18195 | N5: 18195 | O5: 1 | P5: 18195 | Q5: Approved | R5: Initiated | S5: NEFT/RTGS | T5: Supplier | U5: Harish C. Khosla & Co. | V5: Harish C Khosla & Co. | W5: 0 | X5: 0 | Y5: AXIS BANK 921030023943516 - GZB | AC5: -0.4 | AD5: Bank | AE5: -52358625 | AF5: Payable | AG5: -0.4 | AH5: 18195 | AI5: 18195 | AJ5: 18195 | AK5: 18195 | AL5: 0 | AM5: 0 | AN5: 18195 | AO5: 0 | AR5: 0 | AT5: 0 | AU5: 0 | AV5: G.C. Foods Pvt. Ltd.Ghaziabad - Uttar Pradesh-Billing | AW5: 09AACCG2244H1ZS | BB5: N/A | BC5: 45867 | BF5: Ghaziabad | BH5: Cancelled | BI5: 1 | BJ5: Being PAyment Agst-HK/25-26/1106 | BK5: INR Eighteen Thousand, One Hundred And Ninety Five only. | BL5: No | BM5: GCF Letterhead | BO5: AXIS BANK | BP5: 921030023943516 | BR5: INR Eighteen Thousand, One Hundred And Ninety Five only. | BT5: Harish C. Khosla & Co.
A6: PAY/G/25-26/1494 | B6: PAY/G/25-26/1494-1 | C6: PAY/G/23-24/.#### | D6: Receive | E6: 45868 | F6: G. C. Foods Pvt. Ltd. | G6: Debtors - GCF | H6: INR | I6: 9210300223943516 - Axis Bank Ltd. CC Tronica - GCF | J6: INR | K6: 200000 | L6: 1 | M6: 200000 | N6: 200000 | O6: 1 | P6: 200000 | Q6: Approved | R6: Initiated | S6: NEFT/RTGS | T6: Customer | U6: CASH | V6: CASH | W6: 0 | X6: 0 | Y6: AXIS BANK 921030023943516 - GZB | AC6: 89638.06 | AD6: Receivable | AE6: 89638.06 | AF6: Bank | AG6: -49378142 | AH6: 200000 | AI6: 200000 | AJ6: 200000 | AK6: 200000 | AL6: 0 | AM6: 0 | AN6: 200000 | AO6: 0 | AR6: 0 | AT6: 0 | AU6: 0 | AV6: G.C. Foods Pvt. Ltd.Ghaziabad - Uttar Pradesh-Billing | AW6: 09AACCG2244H1ZS | AX6: 10-Bihar | BA6: Unregistered | BB6: N/A | BC6: 45867 | BF6: Ghaziabad | BH6: Cancelled | BI6: 1 | BJ6: Cash Deposit | BK6: INR Two Lakh only. | BL6: No | BM6: GCF Letterhead | BO6: AXIS BANK | BP6: 921030023943516 | BR6: INR Two Lakh only. | BT6: CASH
A7: PAY/M/25-26/0940 | B7: PAY/M/25-26/0940-1 | C7: PAY/G/23-24/.#### | D7: Receive | E7: 45867 | F7: G. C. Foods Pvt. Ltd. | G7: Debtors - GCF | H7: INR | I7: 923020053773708 - Axis Bank - Bihar - GCF | J7: INR | K7: 32752 | L7: 1 | M7: 32752 | N7: 32752 | O7: 1 | P7: 32752 | Q7: Approved | R7: Initiated | S7: NEFT/RTGS | T7: Customer | U7: G.C.Wilmar Private Limited | V7: GC Wilmar Private Limited | W7: 0 | X7: 0 | Y7: AXIS BANK 923020053773708 - BIHAR | AA7: G.C.Wilmar Private Limited-G.C.Wilmar Private Limited | AC7: -4460946.5 | AD7: Receivable | AE7: -4460946.5 | AF7: Bank | AG7: 615.1 | AH7: 32752 | AI7: 32752 | AJ7: 32752 | AK7: 32752 | AL7: 0 | AM7: 0 | AN7: 32752 | AO7: 0 | AR7: 0 | AT7: 0 | AU7: 0 | AV7: GC Foods Muzaffarpur-Billing | AW7: 10AACCG2244H1Z9 | AX7: 10-Bihar | AY7: G.C.Wilmar Private Limited-Billing | AZ7: 10AAICG5386J1ZH | BA7: Registered Regular | BB7: N/A | BC7: 45867 | BF7: Muzaffarpur | BH7: Cancelled | BI7: 0 | BJ7: Amount INR 32752 received from G.C.Wilmar Private Limited Transaction reference no N/A dated 2025-07-29 | BK7: INR Thirty Two Thousand, Seven Hundred And Fifty Two only. | BL7: No | BM7: GCF Letterhead | BO7: AXIS BANK | BP7: 923020053773708 | BR7: INR Thirty Two Thousand, Seven Hundred And Fifty Two only. | BT7: G.C.Wilmar Private Limited
A8: PAY/M/25-26/0937 | B8: PAY/M/25-26/0937-1 | C8: PAY/G/23-24/.#### | D8: Receive | E8: 45866 | F8: G. C. Foods Pvt. Ltd. | G8: Debtors - GCF | H8: INR | I8: 921030030087773 - Axis Bank Ltd. CC Bihar - GCF | J8: INR | K8: 5000 | L8: 1 | M8: 5000 | N8: 5000 | O8: 1 | P8: 5000 | Q8: Approved | R8: Initiated | S8: NEFT/RTGS | T8: Customer | U8: Sujeet Kumar,Kanti | V8: Sujeet Kumar, Kanti | W8: 0 | X8: 0 | Y8: AXIS BANK 921030030087773 - BIHAR | AC8: 59738 | AD8: Receivable | AE8: 59738 | AF8: Bank | AG8: -18267971 | AH8: 5000 | AI8: 5000 | AJ8: 5000 | AK8: 5000 | AL8: 0 | AM8: 0 | AN8: 5000 | AO8: 0 | AR8: 0 | AT8: 0 | AU8: 0 | AV8: GC Foods Muzaffarpur-Billing | AW8: 10AACCG2244H1Z9 | AX8: 10-Bihar | AY8: Sujeet Kumar,Kanti-Billing | BA8: Unregistered | BB8: N/A | BC8: 45866 | BF8: Muzaffarpur | BH8: Cancelled | BI8: 0 | BJ8: Amount INR 5000 received from Sujeet Kumar,Kanti Transaction reference no N/A dated 2025-07-28 | BK8: INR Five Thousand only. | BL8: No | BM8: GCF Letterhead | BO8: AXIS BANK | BP8: 921030030087773 | BR8: INR Five Thousand only. | BT8: Sujeet Kumar,Kanti
A9: PAY/M/25-26/0916 | B9: PAY/M/25-26/0916-1 | C9: PAY/G/23-24/.#### | D9: Pay | E9: 45860 | F9: G. C. Foods Pvt. Ltd. | G9: 921030030087773 - Axis Bank Ltd. CC Bihar - GCF | H9: INR | I9: Creditors - GCF | J9: INR | K9: 750000 | L9: 1 | M9: 750000 | N9: 750000 | O9: 1 | P9: 750000 | Q9: Approved | R9: Initiated | S9: NEFT/RTGS | T9: Employee | U9: Rajesh Kumar Chaudhry (M) | V9: Rajesh Kumar Chaudhry (M) | W9: 0 | X9: 0 | AC9: 230000 | AD9: Bank | AE9: -18602992 | AF9: Payable | AG9: 230000 | AH9: 750000 | AI9: 750000 | AJ9: 750000 | AK9: 750000 | AL9: 0 | AM9: 0 | AN9: 750000 | AO9: 0 | AR9: 0 | AT9: 0 | AU9: 0 | AV9: GC Foods Muzaffarpur-Billing | AW9: 10AACCG2244H1Z9 | BB9: N/A | BC9: 45860 | BF9: Muzaffarpur | BH9: Cancelled | BI9: 0 | BJ9: Amount INR 750000 to Rajesh Kumar Chaudhry (M) Transaction reference no N/A dated 2025-07-22 | BK9: INR Seven Lakh, Fifty Thousand only. | BL9: No | BM9: GCF Letterhead | BR9: INR Seven Lakh, Fifty Thousand only. | BT9: Rajesh Kumar Chaudhry (M)
A10: PAY/G/25-26/1460 | B10: PAY/G/25-26/1460-1 | C10: PAY/G/23-24/.#### | D10: Receive | E10: 45862 | F10: G. C. Foods Pvt. Ltd. | G10: Debtors - GCF | H10: INR | I10: 9210300223943516 - Axis Bank Ltd. CC Tronica - GCF | J10: INR | K10: 32300 | L10: 1 | M10: 32300 | N10: 32300 | O10: 1 | P10: 32300 | Q10: Approved | R10: Initiated | S10: NEFT/RTGS | T10: Customer | U10: Chacha Tau Chap | V10: Chacha Tau Chap | W10: 0 | X10: 0 | Y10: AXIS BANK 921030023943516 - GZB | AC10: -38902 | AD10: Receivable | AE10: -38902 | AF10: Bank | AG10: -52039112 | AH10: 32300 | AI10: 32300 | AJ10: 32300 | AK10: 32300 | AL10: 0 | AM10: 0 | AN10: 32300 | AO10: 0 | AR10: 0 | AT10: 0 | AU10: 0 | AV10: G.C. Foods Pvt. Ltd.Ghaziabad - Uttar Pradesh-Billing | AW10: 09AACCG2244H1ZS | AX10: 07-Delhi | AY10: Chacha Tau Chap-Billing | AZ10: 07DCJPA3280A1Z5 | BA10: Registered Regular | BB10: N/A | BC10: 45862 | BF10: Ghaziabad | BH10: Cancelled | BI10: 1 | BJ10: Pay In Advance | BK10: INR Thirty Two Thousand, Three Hundred only. | BL10: No | BM10: GCF Letterhead | BO10: AXIS BANK | BP10: 921030023943516 | BR10: INR Thirty Two Thousand, Three Hundred only. | BT10: Chacha Tau Chap
A11: PAY/G/23-24/0882 | B11: PAY/G/23-24/0882-1 | C11: PAY/G/23-24/.#### | D11: Pay | E11: 45860 | F11: G. C. Foods Pvt. Ltd. | G11: 923020053773708 - Axis Bank - Bihar - GCF | H11: INR | I11: Creditors - GCF | J11: INR | K11: 750000 | L11: 1 | M11: 750000 | N11: 750000 | O11: 1 | P11: 750000 | Q11: Approved | R11: Initiated | S11: NEFT/RTGS | T11: Employee | U11: Rajesh Kumar Chaudhry (M) | V11: Rajesh Kumar Chaudhry (M) | W11: 0 | X11: 0 | Y11: AXIS BANK 923020053773708 - BIHAR | AC11: 230000 | AD11: Bank | AE11: 570.1 | AF11: Payable | AG11: 230000 | AH11: 750000 | AI11: 750000 | AJ11: 750000 | AK11: 750000 | AL11: 0 | AM11: 0 | AN11: 750000 | AO11: 0 | AR11: 0 | AT11: 0 | AU11: 0 | AV11: GC Foods Muzaffarpur-Billing | AW11: 10AACCG2244H1Z9 | BB11: N/A | BC11: 45860 | BF11: Muzaffarpur | BH11: Cancelled | BI11: 0 | BJ11: Amount INR 750000 to Rajesh Kumar Chaudhry (M) Transaction reference no N/A dated 2025-07-22 | BK11: INR Seven Lakh, Fifty Thousand only. | BL11: No | BM11: GCF Letterhead | BO11: AXIS BANK | BP11: 923020053773708 | BR11: INR Seven Lakh, Fifty Thousand only. | BT11: Rajesh Kumar Chaudhry (M)
A12: PAY/M/25-26/0911 | B12: PAY/M/25-26/0911-1 | C12: PAY/G/23-24/.#### | D12: Receive | E12: 45861 | F12: G. C. Foods Pvt. Ltd. | G12: Debtors - GCF | H12: INR | I12: 923020053773708 - Axis Bank - Bihar - GCF | J12: INR | K12: 1000000 | L12: 1 | M12: 1000000 | N12: 1000000 | O12: 1 | P12: 1000000 | Q12: Approved | R12: Initiated | S12: NEFT/RTGS | T12: Customer | U12: G.C.Wilmar Private Limited | V12: GC Wilmar Private Limited | W12: 0 | X12: 0 | Y12: AXIS BANK 923020053773708 - BIHAR | AA12: G.C.Wilmar Private Limited-G.C.Wilmar Private Limited | AC12: -2863732.7 | AD12: Receivable | AE12: -2863732.7 | AF12: Bank | AG12: 570.1 | AH12: 1000000 | AI12: 1000000 | AJ12: 1000000 | AK12: 1000000 | AL12: 0 | AM12: 0 | AN12: 1000000 | AO12: 0 | AR12: 0 | AT12: 0 | AU12: 0 | AV12: GC Foods Muzaffarpur-Billing | AW12: 10AACCG2244H1Z9 | AX12: 10-Bihar | AY12: G.C.Wilmar Private Limited-Billing | AZ12: 10AHOPS6771R1ZF | BA12: Registered Regular | BB12: N/A | BC12: 45861 | BF12: Muzaffarpur | BH12: Cancelled | BI12: 0 | BJ12: Amount INR 1000000 received from G.C.Wilmar Private Limited Transaction reference no N/A dated 2025-07-23 | BK12: INR Ten Lakh only. | BL12: No | BM12: GCF Letterhead | BO12: AXIS BANK | BP12: 923020053773708 | BR12: INR Ten Lakh only. | BT12: G.C.Wilmar Private Limited
A13: PAY/G/23-24/0881 | B13: PAY/G/23-24/0881-1 | C13: PAY/G/23-24/.#### | D13: Pay | E13: 45859 | F13: G. C. Foods Pvt. Ltd. | G13: 9210300223943516 - Axis Bank Ltd. CC Tronica - GCF | H13: INR | I13: Creditors - GCF | J13: INR | K13: 21000 | L13: 1 | M13: 21000 | N13: 21000 | O13: 1 | P13: 21000 | Q13: Approved | R13: Initiated | S13: NEFT/RTGS | T13: Supplier | U13: G.C.WILMAR Private Limited | V13: G.C.WILMAR Private Limited | W13: 0 | X13: 0 | Y13: AXIS BANK 921030023943516 - GZB | AC13: -630600 | AD13: Bank | AE13: -51845742 | AF13: Payable | AG13: 68580934 | AH13: 21000 | AI13: 21000 | AJ13: 21000 | AK13: 21000 | AL13: 0 | AM13: 0 | AN13: 21000 | AO13: 0 | AR13: 0 | AT13: 0 | AU13: 0 | AV13: GC Foods Muzaffarpur-Billing | AW13: 10AACCG2244H1Z9 | BB13: N/A | BC13: 45859 | BF13: Muzaffarpur | BH13: Cancelled | BI13: 0 | BJ13: Amount INR 21000 to G.C.WILMAR Private Limited Transaction reference no N/A dated 2025-07-21 | BK13: INR Twenty One Thousand only. | BL13: No | BM13: GCF Letterhead | BO13: AXIS BANK | BP13: 921030023943516 | BR13: INR Twenty One Thousand only. | BT13: G.C.WILMAR Private Limited
A14: PAY/N/25-26/0572 | B14: PAY/N/25-26/0572-1 | C14: PAY/G/23-24/.#### | D14: Pay | E14: 45861 | F14: G. C. Foods Pvt. Ltd. | G14: 921030030087786 - Axis Bank Ltd. CC Noida - GCF | H14: INR | I14: Creditors - GCF | J14: INR | K14: 20000 | L14: 1 | M14: 20000 | N14: 20000 | O14: 1 | P14: 20000 | Q14: Approved | R14: Initiated | S14: NEFT/RTGS | T14: Supplier | U14: Frontier Automobiles Private Limited | V14: Frontier Automobiles Private Limited | W14: 0 | X14: 0 | Y14: AXIS BANK 921030030087786 - NOIDA | AC14: 444943 | AD14: Bank | AE14: -4854404.6 | AF14: Payable | AG14: 444943 | AH14: 20000 | AI14: 20000 | AJ14: 20000 | AK14: 20000 | AL14: 0 | AM14: 0 | AN14: 20000 | AO14: 0 | AR14: 0 | AT14: 0 | AU14: 0 | AV14: G.C. Foods Pvt. Ltd. Noida - Uttar Pradesh (Shipping) | AW14: 09AACCG2244H1ZS | BB14: N/A | BC14: 45861 | BF14: Noida | BH14: Cancelled | BI14: 0 | BJ14: Amount INR 20000 to Frontier Automobiles Private Limited Transaction reference no N/A dated 2025-07-23 | BK14: INR Twenty Thousand only. | BL14: No | BM14: GCF Letterhead | BO14: AXIS BANK | BP14: 921030030087786 | BR14: INR Twenty Thousand only. | BT14: Frontier Automobiles Private Limited
A15: PAY/G/25-26/1391 | B15: PAY/G/25-26/1391-1 | C15: PAY/G/23-24/.#### | D15: Receive | E15: 45856 | F15: G. C. Foods Pvt. Ltd. | G15: Debtors - GCF | H15: INR | I15: 9210300223943516 - Axis Bank Ltd. CC Tronica - GCF | J15: INR | K15: 145000 | L15: 1 | M15: 145000 | N15: 145000 | O15: 1 | P15: 145000 | Q15: Approved | R15: Initiated | S15: NEFT/RTGS | T15: Customer | U15: M/S Puja Enterprises | V15: M/S Puja Enterprises | W15: 0 | X15: 0 | Y15: AXIS BANK 921030023943516 - GZB | AC15: 41223 | AD15: Receivable | AE15: 41223 | AF15: Bank | AG15: -52328248 | AH15: 145000 | AI15: 145000 | AJ15: 145000 | AK15: 145000 | AL15: 0 | AM15: 0 | AN15: 145000 | AO15: 0 | AR15: 0 | AT15: 0 | AU15: 0 | AV15: G.C. Foods Pvt. Ltd.Ghaziabad - Uttar Pradesh-Billing | AW15: 09AACCG2244H1ZS | AX15: 07-Delhi | AY15: M/S Puja Enterprises-Billing | AZ15: 07BRPPJ6469M1ZV | BA15: Registered Regular | BB15: N/A | BC15: 45858 | BF15: Ghaziabad | BH15: Cancelled | BI15: 0 | BJ15: Amount INR 145000 received from M/S Puja Enterprises Transaction reference no N/A dated 2025-07-20 | BK15: INR One Lakh, Forty Five Thousand only. | BL15: No | BO15: AXIS BANK | BP15: 921030023943516 | BR15: INR One Lakh, Forty Five Thousand only. | BT15: M/S Puja Enterprises
A16: PAY/G/25-26/1379 | B16: PAY/G/25-26/1379-1 | C16: PAY/G/23-24/.#### | D16: Receive | E16: 45857 | F16: G. C. Foods Pvt. Ltd. | G16: Debtors - GCF | H16: INR | I16: 9210300223943516 - Axis Bank Ltd. CC Tronica - GCF | J16: INR | K16: 10000 | L16: 1 | M16: 10000 | N16: 10000 | O16: 1 | P16: 10000 | Q16: Approved | R16: Initiated | S16: NEFT/RTGS | T16: Customer | U16: J.K. Traders | V16: J.K. Traders | W16: 0 | X16: 0 | Y16: AXIS BANK 921030023943516 - GZB | AC16: -34641 | AD16: Receivable | AE16: -34641 | AF16: Bank | AG16: -51738887 | AH16: 10000 | AI16: 10000 | AJ16: 10000 | AK16: 10000 | AL16: 0 | AM16: 0 | AN16: 10000 | AO16: 0 | AR16: 0 | AT16: 0 | AU16: 0 | AV16: G.C. Foods Pvt. Ltd.Ghaziabad - Uttar Pradesh-Billing | AW16: 09AACCG2244H1ZS | AX16: 07-Delhi | AY16: J.K. Traders-Billing | BA16: Unregistered | BB16: N/A | BC16: 45857 | BF16: Ghaziabad | BH16: Cancelled | BI16: 0 | BJ16: Amount INR 10000 received from J.K. Traders Transaction reference no N/A dated 2025-07-19 | BK16: INR Ten Thousand only. | BL16: No | BO16: AXIS BANK | BP16: 921030023943516 | BR16: INR Ten Thousand only. | BT16: J.K. Traders
A17: PAY/N/25-26/0554 | B17: PAY/N/25-26/0554-1 | C17: PAY/G/23-24/.#### | D17: Receive | E17: 45849 | F17: G. C. Foods Pvt. Ltd. | G17: Debtors - GCF | H17: INR | I17: 921030030087786 - Axis Bank Ltd. CC Noida - GCF | J17: INR | K17: 339140 | L17: 1 | M17: 339140 | N17: 339140 | O17: 1 | P17: 339140 | Q17: Approved | R17: Initiated | S17: NEFT/RTGS | T17: Customer | U17: E-powertech | V17: E-powertech | W17: 0 | X17: 0 | Y17: AXIS BANK 921030030087786 - NOIDA | AC17: 0 | AD17: Receivable | AE17: -16957861 | AF17: Bank | AG17: -4861280.3 | AH17: 339140 | AI17: 339140 | AJ17: 339140 | AK17: 339140 | AL17: 0 | AM17: 0 | AN17: 339140 | AO17: 0 | AR17: 0 | AT17: 0 | AU17: 0 | AV17: G.C. Foods Pvt. Ltd. Noida - Uttar Pradesh (Shipping) | AW17: 09AACCG2244H1ZS | AX17: 10-Bihar | BA17: Unregistered | BB17: N/A | BC17: 45849 | BF17: Noida | BH17: Cancelled | BI17: 0 | BJ17: Amount INR 339140 received from E-powertech Transaction reference no N/A dated 2025-07-11 | BK17: INR Three Lakh, Thirty Nine Thousand, One Hundred And Forty only. | BL17: No | BO17: AXIS BANK | BP17: 921030030087786 | BR17: INR Three Lakh, Thirty Nine Thousand, One Hundred And Forty only. | BT17: E-powertech
A18: PAY/M/25-26/0862 | B18: PAY/M/25-26/0862-1 | C18: PAY/G/23-24/.#### | D18: Pay | E18: 45769 | F18: G. C. Foods Pvt. Ltd. | G18: 921030030087773 - Axis Bank Ltd. CC Bihar - GCF | H18: INR | I18: Creditors - GCF | J18: INR | K18: 48000 | L18: 1 | M18: 48000 | N18: 48000 | O18: 1 | P18: 48000 | Q18: Approved | R18: Initiated | S18: NEFT/RTGS | T18: Employee | U18: Shashi Kant Bhalla (M) | V18: Shashi Kant Bhalla (M) | W18: 0 | X18: 0 | AC18: 0 | AD18: Bank | AE18: -19973354 | AF18: Payable | AG18: -5936117.7 | AH18: 48000 | AI18: 48000 | AJ18: 48000 | AK18: 48000 | AL18: 0 | AM18: 0 | AN18: 48000 | AO18: 0 | AR18: 0 | AT18: 0 | AU18: 0 | AV18: GC Foods Muzaffarpur-Billing | AW18: 10AACCG2244H1Z9 | BB18: N/A | BC18: 45769 | BF18: Muzaffarpur | BH18: Cancelled | BI18: 0 | BJ18: Amount INR 48000 to Shashi Kant Bhalla (M) Transaction reference no N/A dated 2025-04-22 | BK18: INR Forty Eight Thousand only. | BL18: No | BR18: INR Forty Eight Thousand only. | BT18: Shashi Kant Bhalla (M)
A19: PAY/M/25-26/0844-2 | B19: PAY/M/25-26/0844-2-1 | C19: PAY/G/23-24/.#### | D19: Receive | E19: 45855 | F19: G. C. Foods Pvt. Ltd. | G19: Debtors - GCF | H19: INR | I19: 921030030087773 - Axis Bank Ltd. CC Bihar - GCF | J19: INR | K19: 119892 | L19: 1 | M19: 119892 | N19: 119892 | O19: 1 | P19: 119892 | Q19: Approved | R19: Initiated | S19: NEFT/RTGS | T19: Customer | U19: Jay Mata TranportPan.No.AHUPT5943Q | V19: Jay Mata TranportPan.No.AHUPT5943Q | W19: 0 | X19: 0 | Y19: AXIS BANK 921030030087773 - BIHAR | AC19: 0 | AD19: Receivable | AE19: -16202970 | AF19: Bank | AG19: -19646286 | AH19: 119892 | AI19: 119892 | AJ19: 119892 | AK19: 119892 | AL19: 0 | AM19: 0 | AN19: 119892 | AO19: 0 | AR19: 0 | AT19: 0 | AU19: 0 | AV19: GC Foods Muzaffarpur-Billing | AW19: 10AACCG2244H1Z9 | AX19: 10-Bihar | BA19: Unregistered | BB19: N/A | BC19: 45855 | BF19: Muzaffarpur | BH19: Cancelled | BI19: 0 | BJ19: Amount INR 119892 received from Jay Mata TranportPan.No.AHUPT5943Q Transaction reference no N/A dated 2025-07-17 | BK19: INR One Lakh, Nineteen Thousand, Eight Hundred And Ninety Two only. | BL19: No | BO19: AXIS BANK | BP19: 921030030087773 | BR19: INR One Lakh, Nineteen Thousand, Eight Hundred And Ninety Two only. | BT19: Jay Mata TranportPan.No.AHUPT5943Q
A20: PAY/M/25-26/0844-1 | B20: PAY/M/25-26/0844-2 | C20: PAY/G/23-24/.#### | D20: Receive | E20: 45855 | F20: G. C. Foods Pvt. Ltd. | G20: Debtors - GCF | H20: INR | I20: 9210300223943516 - Axis Bank Ltd. CC Tronica - GCF | J20: INR | K20: 119892 | L20: 1 | M20: 119892 | N20: 119892 | O20: 1 | P20: 119892 | Q20: Approved | R20: Initiated | S20: NEFT/RTGS | T20: Customer | U20: Jay Mata TranportPan.No.AHUPT5943Q | V20: Jay Mata TranportPan.No.AHUPT5943Q | W20: 0 | X20: 0 | Y20: AXIS BANK 921030030087773 - BIHAR | AC20: 0 | AD20: Receivable | AE20: -16202970 | AF20: Bank | AG20: -54154327 | AH20: 119892 | AI20: 119892 | AJ20: 119892 | AK20: 119892 | AL20: 0 | AM20: 0 | AN20: 119892 | AO20: 0 | AR20: 0 | AT20: 0 | AU20: 0 | AV20: GC Foods Muzaffarpur-Billing | AW20: 10AACCG2244H1Z9 | AX20: 10-Bihar | BA20: Unregistered | BB20: N/A | BC20: 45855 | BF20: Muzaffarpur | BH20: Cancelled | BI20: 0 | BJ20: Amount INR 119892 received from Jay Mata TranportPan.No.AHUPT5943Q Transaction reference no N/A dated 2025-07-17 | BK20: INR One Lakh, Nineteen Thousand, Eight Hundred And Ninety Two only. | BL20: No | BO20: AXIS BANK | BP20: 921030030087773 | BR20: INR One Lakh, Nineteen Thousand, Eight Hundred And Ninety Two only. | BT20: Jay Mata TranportPan.No.AHUPT5943Q
A21: PAY/M/25-26/0844 | B21: PAY/M/25-26/0844-1 | C21: PAY/G/23-24/.#### | D21: Receive | E21: 45856 | F21: G. C. Foods Pvt. Ltd. | G21: Debtors - GCF | H21: INR | I21: 921030030087773 - Axis Bank Ltd. CC Bihar - GCF | J21: INR | K21: 119892 | L21: 1 | M21: 119892 | N21: 119892 | O21: 1 | P21: 119892 | Q21: Approved | R21: Initiated | T21: Customer | U21: Jay Mata TranportPan.No.AHUPT5943Q | V21: Jay Mata TranportPan.No.AHUPT5943Q | W21: 0 | X21: 0 | Y21: AXIS BANK 921030030087773 - BIHAR | AC21: 0 | AD21: Receivable | AE21: -16202970 | AF21: Bank | AG21: -18873949 | AH21: 119892 | AI21: 119892 | AJ21: 119892 | AK21: 119892 | AL21: 0 | AM21: 0 | AN21: 119892 | AO21: 0 | AR21: 0 | AT21: 0 | AU21: 0 | AV21: GC Foods Muzaffarpur-Billing | AW21: 10AACCG2244H1Z9 | AX21: 10-Bihar | BA21: Unregistered | BB21: N/A | BC21: 45855 | BF21: Muzaffarpur | BH21: Cancelled | BI21: 0 | BJ21: Amount INR 119892 received from Jay Mata TranportPan.No.AHUPT5943Q Transaction reference no N/A dated 2025-07-17 | BK21: INR One Lakh, Nineteen Thousand, Eight Hundred And Ninety Two only. | BL21: No | BO21: AXIS BANK | BP21: 921030030087773 | BR21: INR One Lakh, Nineteen Thousand, Eight Hundred And Ninety Two only. | BT21: Jay Mata TranportPan.No.AHUPT5943Q
A22: PAY/G/25-26/1360 | B22: PAY/G/25-26/1360-1 | C22: PAY/G/23-24/.#### | D22: Pay | E22: 45855 | F22: G. C. Foods Pvt. Ltd. | G22: 9210300223943516 - Axis Bank Ltd. CC Tronica - GCF | H22: INR | I22: Creditors - GCF | J22: INR | K22: 27080 | L22: 1 | M22: 27080 | N22: 27080 | O22: 1 | P22: 27080 | Q22: Approved | R22: Initiated | S22: NEFT/RTGS | T22: Supplier | U22: Mahaadev Traders | V22: Mahaadev Traders | W22: 0 | X22: 0 | Y22: AXIS BANK 921030023943516 - GZB | AC22: -1655649.8 | AD22: Bank | AE22: -52588746 | AF22: Payable | AG22: -1655649.8 | AH22: 27080 | AI22: 27080 | AJ22: 27080 | AK22: 27080 | AL22: 0 | AM22: 0 | AN22: 27080 | AO22: 0 | AR22: 0 | AT22: 0 | AU22: 0 | AV22: G.C. Foods Pvt. Ltd.Ghaziabad - Uttar Pradesh-Billing | AW22: 09AACCG2244H1ZS | BB22: N/A | BC22: 45855 | BF22: Ghaziabad | BH22: Cancelled | BI22: 0 | BJ22: Amount INR 27080 to Mahaadev Traders Transaction reference no N/A dated 2025-07-17 | BK22: INR Twenty Seven Thousand And Eighty only. | BL22: No | BO22: AXIS BANK | BP22: 921030023943516 | BR22: INR Twenty Seven Thousand And Eighty only. | BT22: Mahaadev Traders
A23: PAY/G/25-26/1355 | B23: PAY/G/25-26/1355-1 | C23: PAY/G/23-24/.#### | D23: Pay | E23: 45855 | F23: G. C. Foods Pvt. Ltd. | G23: 9210300223943516 - Axis Bank Ltd. CC Tronica - GCF | H23: INR | I23: Creditors - GCF | J23: INR | K23: 1328158 | L23: 1 | M23: 1328158 | N23: 1328158 | O23: 1 | P23: 1328158 | Q23: Approved | R23: Initiated | S23: NEFT/RTGS | T23: Supplier | U23: Mahaadev Traders | V23: Mahaadev Traders | W23: 0 | X23: 0 | Y23: AXIS BANK 921030023943516 - GZB | AC23: -2983807.8 | AD23: Bank | AE23: -53318128 | AF23: Payable | AG23: -2983807.8 | AH23: 1328158 | AI23: 1328158 | AJ23: 1328158 | AK23: 1328158 | AL23: 0 | AM23: 0 | AN23: 1328158 | AO23: 0 | AR23: 0 | AT23: 0 | AU23: 0 | AV23: G.C. Foods Pvt. Ltd.Ghaziabad - Uttar Pradesh-Billing | AW23: 09AACCG2244H1ZS | BB23: N/A | BC23: 45855 | BF23: Ghaziabad | BH23: Cancelled | BI23: 0 | BJ23: Amount INR 1328158 to Mahaadev Traders Transaction reference no N/A dated 2025-07-17 | BK23: INR Thirteen Lakh, Twenty Eight Thousand, One Hundred And Fifty Eight only. | BL23: No | BO23: AXIS BANK | BP23: 921030023943516 | BR23: INR Thirteen Lakh, Twenty Eight Thousand, One Hundred And Fifty Eight only. | BT23: Mahaadev Traders
A24: PAY/M/25-26/0826 | B24: PAY/M/25-26/0826-1 | C24: PAY/G/23-24/.#### | D24: Pay | E24: 45850 | F24: G. C. Foods Pvt. Ltd. | G24: 921030030087773 - Axis Bank Ltd. CC Bihar - GCF | H24: INR | I24: Creditors - GCF | J24: INR | K24: 38709 | L24: 1 | M24: 38709 | N24: 38709 | O24: 1 | P24: 38709 | Q24: Approved | R24: Initiated | S24: NEFT/RTGS | T24: Supplier | U24: GC foods Pvt Ltd (T) | V24: GC foods Pvt Ltd (T) | W24: 0 | X24: 0 | Y24: AXIS BANK 921030030087773 - BIHAR | AC24: 42792485 | AD24: Bank | AE24: -19738705 | AF24: Payable | AG24: 42792485 | AH24: 38709 | AI24: 38709 | AJ24: 38709 | AK24: 38709 | AL24: 0 | AM24: 0 | AN24: 38709 | AO24: 0 | AR24: 0 | AT24: 0 | AU24: 0 | AV24: GC Foods Muzaffarpur-Billing | AW24: 10AACCG2244H1Z9 | BB24: N/A | BC24: 45850 | BF24: Muzaffarpur | BH24: Cancelled | BI24: 0 | BJ24: Amount INR 38709 to GC foods Pvt Ltd (T) Transaction reference no N/A dated 2025-07-12 | BK24: INR Thirty Eight Thousand, Seven Hundred And Nine only. | BL24: No | BO24: AXIS BANK | BP24: 921030030087773 | BR24: INR Thirty Eight Thousand, Seven Hundred And Nine only. | BT24: GC foods Pvt Ltd (T)
A25: PAY/N/25-26/0522 | B25: PAY/N/25-26/0522-1 | C25: PAY/G/23-24/.#### | D25: Receive | E25: 45846 | F25: G. C. Foods Pvt. Ltd. | G25: Debtors - GCF | H25: INR | I25: 923020017959018 - Axis Bank - NOIDA - GCF | J25: INR | K25: 1771.89 | L25: 1 | M25: 1771.89 | N25: 1771.89 | O25: 1 | P25: 1771.89 | Q25: Approved | R25: Initiated | S25: NEFT/RTGS | T25: Customer | U25: DTDC EXPRESS (Courier) | V25: DTDC EXPRESS (Courier) | W25: 0 | X25: 0 | Y25: AXIS BANK 923020017959018 -NOIDA | AA25: Amrit Varsha-DTDC EXPRESS SERVICE | AC25: 4125.22 | AD25: Receivable | AE25: 4125.22 | AF25: Bank | AG25: 24288.68 | AH25: 1771.89 | AI25: 1771.89 | AJ25: 1771.89 | AK25: 1771.89 | AL25: 0 | AM25: 0 | AN25: 1771.89 | AO25: 0 | AR25: 0 | AT25: 0 | AU25: 0 | AV25: G.C. Foods Pvt. Ltd. Noida - Uttar Pradesh (Shipping) | AW25: 09AACCG2244H1ZS | AX25: 27-Maharashtra | AY25: DTDC EXPRESS SERVICE-Billing-18 | BA25: Unregistered | BB25: N/A | BC25: 45846 | BF25: Noida | BH25: Cancelled | BI25: 0 | BJ25: Amount INR 1771.89 received from DTDC EXPRESS (Courier) Transaction reference no N/A dated 2025-07-08 | BK25: INR One Thousand, Seven Hundred And Seventy One and Eighty Nine Paisa only. | BL25: No | BO25: AXIS BANK | BP25: 923020017959018 | BR25: INR One Thousand, Seven Hundred And Seventy One and Eighty Nine Paisa only. | BT25: DTDC EXPRESS (Courier)
A26: PAY/M/25-26/0769-1 | B26: PAY/M/25-26/0769-2 | C26: PAY/G/23-24/.#### | D26: Pay | E26: 45845 | F26: G. C. Foods Pvt. Ltd. | G26: 921030030087773 - Axis Bank Ltd. CC Bihar - GCF | H26: INR | I26: Creditors - GCF | J26: INR | K26: 30600 | L26: 1 | M26: 30600 | N26: 30600 | O26: 1 | P26: 30600 | Q26: Approved | R26: Initiated | S26: NEFT/RTGS | T26: Supplier | U26: Jogendra jee, Patna | V26: Jogendra jee, Patna | W26: 0 | X26: 0 | Y26: AXIS BANK 921030030087773 - BIHAR | AC26: -30000 | AD26: Bank | AE26: -18051699 | AF26: Payable | AG26: -30000 | AH26: 30600 | AI26: 30600 | AJ26: 30600 | AK26: 30600 | AL26: 0 | AM26: 0 | AN26: 30600 | AO26: 0 | AR26: 0 | AT26: 0 | AU26: 0 | AV26: GC Foods Muzaffarpur-Billing | AW26: 10AACCG2244H1Z9 | BB26: N/A | BC26: 45845 | BF26: Muzaffarpur | BH26: Cancelled | BI26: 0 | BJ26: Amount INR 30600 to Jogendra jee, Patna Transaction reference no N/A dated 2025-07-07 | BK26: INR Thirty Thousand, Six Hundred only. | BL26: No | BO26: AXIS BANK | BP26: 921030030087773 | BR26: INR Thirty Thousand, Six Hundred only. | BT26: Jogendra jee, Patna
A27: PAY/N/25-26/0513 | B27: PAY/N/25-26/0513-1 | C27: PAY/G/23-24/.#### | D27: Pay | E27: 45848 | F27: G. C. Foods Pvt. Ltd. | G27: 921030030087786 - Axis Bank Ltd. CC Noida - GCF | H27: INR | I27: Creditors - GCF | J27: INR | K27: 339140 | L27: 1 | M27: 339140 | N27: 339140 | O27: 1 | P27: 339140 | Q27: Approved | R27: Initiated | S27: NEFT/RTGS | T27: Supplier | U27: E Powertech | V27: E Power Technologies | W27: 0 | X27: 0 | Y27: AXIS BANK 921030030087786 - NOIDA | AC27: 772380 | AD27: Bank | AE27: -4857980.3 | AF27: Payable | AG27: 772380 | AH27: 339140 | AI27: 339140 | AJ27: 339140 | AK27: 339140 | AL27: 0 | AM27: 0 | AN27: 339140 | AO27: 0 | AR27: 0 | AT27: 0 | AU27: 0 | AV27: G.C. Foods Pvt. Ltd. Noida - Uttar Pradesh (Shipping) | AW27: 09AACCG2244H1ZS | BB27: N/A | BC27: 45848 | BF27: Noida | BH27: Cancelled | BI27: 0 | BJ27: Amount INR 339140 to E Power Technologies Transaction reference no N/A dated 2025-07-10 | BK27: INR Three Lakh, Thirty Nine Thousand, One Hundred And Forty only. | BL27: No | BO27: AXIS BANK | BP27: 921030030087786 | BR27: INR Three Lakh, Thirty Nine Thousand, One Hundred And Forty only. | BT27: E Power Technologies
A28: PAY/N/25-26/0505 | B28: PAY/N/25-26/0505-1 | C28: PAY/G/23-24/.#### | D28: Pay | E28: 45847 | F28: G. C. Foods Pvt. Ltd. | G28: 921030030087786 - Axis Bank Ltd. CC Noida - GCF | H28: INR | I28: Creditors - GCF | J28: INR | K28: 6333 | L28: 1 | M28: 6333 | N28: 6333 | O28: 1 | P28: 6333 | Q28: Approved | R28: Initiated | S28: NEFT/RTGS | T28: Employee | U28: Ankit Kumar - Staff Noida | V28: Ankit Kumar - Staff Noida | W28: 0 | X28: 0 | AC28: 0 | AD28: Bank | AE28: -4914951.3 | AF28: Payable | AG28: 68176968 | AH28: 6333 | AI28: 6333 | AJ28: 6333 | AK28: 6333 | AL28: 0 | AM28: 0 | AN28: 6333 | AO28: 0 | AR28: 0 | AT28: 0 | AU28: 0 | AV28: G.C. Foods Pvt. Ltd. Noida - Uttar Pradesh (Shipping) | AW28: 09AACCG2244H1ZS | BB28: N/A | BC28: 45847 | BF28: Noida | BH28: Cancelled | BI28: 0 | BJ28: Amount INR 6333 to Ankit Kumar - Staff Noida Transaction reference no N/A dated 2025-07-09 | BK28: INR Six Thousand, Three Hundred And Thirty Three only. | BL28: No | BR28: INR Six Thousand, Three Hundred And Thirty Three only. | BT28: Ankit Kumar - Staff Noida
A29: PAY/N/25-26/0478 | B29: PAY/N/25-26/0478-1 | C29: PAY/G/23-24/.#### | D29: Pay | E29: 45846 | F29: G. C. Foods Pvt. Ltd. | G29: 921030030087786 - Axis Bank Ltd. CC Noida - GCF | H29: INR | I29: Creditors - GCF | J29: INR | K29: 31500 | L29: 1 | M29: 31500 | N29: 31500 | O29: 1 | P29: 31500 | Q29: Approved | R29: Initiated | S29: NEFT/RTGS | T29: Supplier | U29: GC foods Pvt Ltd Bihar | V29: GC foods Pvt Ltd Bihar | W29: 0 | X29: 0 | Y29: AXIS BANK 921030030087786 - NOIDA | AC29: 5195000 | AD29: Bank | AE29: -4896731.3 | AF29: Payable | AG29: 5195000 | AH29: 31500 | AI29: 31500 | AJ29: 31500 | AK29: 31500 | AL29: 0 | AM29: 0 | AN29: 31500 | AO29: 0 | AR29: 0 | AT29: 0 | AU29: 0 | AV29: G.C. Foods Pvt. Ltd. Noida - Uttar Pradesh (Shipping) | AW29: 09AACCG2244H1ZS | BB29: N/A | BC29: 45846 | BF29: Noida | BH29: Cancelled | BI29: 0 | BJ29: Amount INR 31500 to GC foods Pvt Ltd Bihar Transaction reference no N/A dated 2025-07-08 | BK29: INR Thirty One Thousand, Five Hundred only. | BL29: No | BO29: AXIS BANK | BP29: 921030030087786 | BR29: INR Thirty One Thousand, Five Hundred only. | BT29: GC foods Pvt Ltd Bihar
A30: PAY/N/25-26/0462 | B30: PAY/N/25-26/0462-1 | C30: PAY/G/23-24/.#### | D30: Pay | E30: 45845 | F30: G. C. Foods Pvt. Ltd. | G30: 9210300223943516 - Axis Bank Ltd. CC Tronica - GCF | H30: INR | I30: Creditors - GCF | J30: INR | K30: 3300 | L30: 1 | M30: 3300 | N30: 3300 | O30: 1 | P30: 3300 | Q30: Approved | R30: Initiated | S30: NEFT/RTGS | T30: Employee | U30: Kanhiya Lal Sales - NCR | V30: Kanhiya Lal Sales - NCR | W30: 0 | X30: 0 | AC30: 10875 | AD30: Bank | AE30: -53173281 | AF30: Payable | AG30: 10875 | AH30: 3300 | AI30: 3300 | AJ30: 3300 | AK30: 3300 | AL30: 0 | AM30: 0 | AN30: 3300 | AO30: 0 | AR30: 0 | AT30: 0 | AU30: 0 | AV30: G.C. Foods Pvt. Ltd. Noida - Uttar Pradesh (Shipping) | AW30: 09AACCG2244H1ZS | BB30: N/A | BC30: 45845 | BF30: Noida | BH30: Cancelled | BI30: 0 | BJ30: Amount INR 3300 to Kanhiya Lal Sales - NCR Transaction reference no N/A dated 2025-07-07 | BK30: INR Three Thousand, Three Hundred only. | BL30: No | BR30: INR Three Thousand, Three Hundred only. | BT30: Kanhiya Lal Sales - NCR
A31: PAY/N/25-26/0455-1 | B31: PAY/N/25-26/0455-2 | C31: PAY/G/23-24/.#### | D31: Pay | E31: 45843 | F31: G. C. Foods Pvt. Ltd. | G31: 921030030087786 - Axis Bank Ltd. CC Noida - GCF | H31: INR | I31: Creditors - GCF | J31: INR | K31: 34043 | L31: 1 | M31: 34043 | N31: 34043 | O31: 1 | P31: 34043 | Q31: Approved | R31: Initiated | S31: NEFT/RTGS | T31: Supplier | U31: Galaxy Sivtek Private Limited | V31: Galaxy Sivtek Private Limited | W31: 0 | X31: 0 | Y31: AXIS BANK 921030030087786 - NOIDA | AC31: 0 | AD31: Bank | AE31: -5133173.3 | AF31: Payable | AG31: 61551320 | AH31: 34043 | AI31: 34043 | AJ31: 34043 | AK31: 34043 | AL31: 0 | AM31: 0 | AN31: 34043 | AO31: 0 | AR31: 0 | AT31: 0 | AU31: 0 | AV31: G.C. Foods Pvt. Ltd. Noida - Uttar Pradesh (Shipping) | AW31: 09AACCG2244H1ZS | BB31: N/A | BC31: 45843 | BF31: Noida | BH31: Cancelled | BI31: 0 | BJ31: Amount INR 34043 to Galaxy Sivtek Private Limited Transaction reference no N/A dated 2025-07-05 | BK31: INR Thirty Four Thousand And Forty Three only. | BL31: No | BO31: AXIS BANK | BP31: 921030030087786 | BR31: INR Thirty Four Thousand And Forty Three only. | BT31: Galaxy Sivtek Private Limited
A32: PAY/N/25-26/0456 | B32: PAY/N/25-26/0456-1 | C32: PAY/G/23-24/.#### | D32: Pay | E32: 45842 | F32: G. C. Foods Pvt. Ltd. | G32: 921030030087786 - Axis Bank Ltd. CC Noida - GCF | H32: INR | I32: Creditors - GCF | J32: INR | K32: 9038 | L32: 1 | M32: 9038 | N32: 9038 | O32: 1 | P32: 9038 | Q32: Approved | R32: Initiated | S32: NEFT/RTGS | T32: Supplier | U32: Gogia Chemical Industries (P) Ltd | V32: Gogia Chemical Industries (P) Ltd | W32: 0 | X32: 0 | Y32: AXIS BANK 921030030087786 - NOIDA | AC32: -9038 | AD32: Bank | AE32: -5167216.3 | AF32: Payable | AG32: -9038 | AH32: 9038 | AI32: 9038 | AJ32: 9038 | AK32: 9038 | AL32: 0 | AM32: 0 | AN32: 9038 | AO32: 0 | AR32: 0 | AT32: 0 | AU32: 0 | AV32: G.C. Foods Pvt. Ltd. Noida - Uttar Pradesh (Shipping) | AW32: 09AACCG2244H1ZS | BB32: N/A | BC32: 45842 | BF32: Noida | BH32: Cancelled | BI32: 0 | BJ32: Amount INR 9038 to Gogia Chemical Industries (P) Ltd Transaction reference no N/A dated 2025-07-04 | BK32: INR Nine Thousand And Thirty Eight only. | BL32: No | BO32: AXIS BANK | BP32: 921030030087786 | BR32: INR Nine Thousand And Thirty Eight only. | BT32: Gogia Chemical Industries (P) Ltd
A33: PAY/N/25-26/0455 | B33: PAY/N/25-26/0455-1 | C33: PAY/G/23-24/.#### | D33: Pay | E33: 45842 | F33: G. C. Foods Pvt. Ltd. | G33: 921030030087786 - Axis Bank Ltd. CC Noida - GCF | H33: INR | I33: Creditors - GCF | J33: INR | K33: 34043 | L33: 1 | M33: 34043 | N33: 34043 | O33: 1 | P33: 34043 | Q33: Approved | R33: Initiated | S33: NEFT/RTGS | T33: Supplier | U33: Galaxy Sivtek Private Limited | V33: Galaxy Sivtek Private Limited | W33: 0 | X33: 0 | Y33: AXIS BANK 921030030087786 - NOIDA | AC33: 0 | AD33: Bank | AE33: -5133173.3 | AF33: Payable | AG33: 61551320 | AH33: 34043 | AI33: 34043 | AJ33: 34043 | AK33: 34043 | AL33: 0 | AM33: 0 | AN33: 34043 | AO33: 0 | AR33: 0 | AT33: 0 | AU33: 0 | AV33: G.C. Foods Pvt. Ltd. Noida - Uttar Pradesh (Shipping) | AW33: 09AACCG2244H1ZS | BB33: N/A | BC33: 45842 | BF33: Noida | BH33: Cancelled | BI33: 0 | BJ33: Amount INR 34043 to Galaxy Sivtek Private Limited Transaction reference no N/A dated 2025-07-04 | BK33: INR Thirty Four Thousand And Forty Three only. | BL33: No | BO33: AXIS BANK | BP33: 921030030087786 | BR33: INR Thirty Four Thousand And Forty Three only. | BT33: Galaxy Sivtek Private Limited
A34: PAY/N/25-26/0454 | B34: PAY/N/25-26/0454-1 | C34: PAY/G/23-24/.#### | D34: Pay | E34: 45842 | F34: G. C. Foods Pvt. Ltd. | G34: 921030030087786 - Axis Bank Ltd. CC Noida - GCF | H34: INR | I34: Creditors - GCF | J34: INR | K34: 130956 | L34: 1 | M34: 130956 | N34: 130956 | O34: 1 | P34: 130956 | Q34: Approved | R34: Initiated | S34: NEFT/RTGS | T34: Supplier | U34: Daulat Ram Rakesh Kumar | V34: Daulat Ram Rakesh Kumar | W34: 0 | X34: 0 | Y34: AXIS BANK 921030030087786 - NOIDA | AC34: -160697.45 | AD34: Bank | AE34: -5002217.3 | AF34: Payable | AG34: -160697.45 | AH34: 130956 | AI34: 130956 | AJ34: 130956 | AK34: 130956 | AL34: 0 | AM34: 0 | AN34: 130956 | AO34: 0 | AR34: 0 | AT34: 0 | AU34: 0 | AV34: G.C. Foods Pvt. Ltd. Noida - Uttar Pradesh (Shipping) | AW34: 09AACCG2244H1ZS | BB34: N/A | BC34: 45842 | BF34: Noida | BH34: Cancelled | BI34: 0 | BJ34: Amount INR 130956 to Daulat Ram Rakesh Kumar Transaction reference no N/A dated 2025-07-04 | BK34: INR One Lakh, Thirty Thousand, Nine Hundred And Fifty Six only. | BL34: No | BO34: AXIS BANK | BP34: 921030030087786 | BR34: INR One Lakh, Thirty Thousand, Nine Hundred And Fifty Six only. | BT34: Daulat Ram Rakesh Kumar
A35: PAY/N/25-26/0453 | B35: PAY/N/25-26/0453-1 | C35: PAY/G/23-24/.#### | D35: Pay | E35: 45842 | F35: G. C. Foods Pvt. Ltd. | G35: 921030030087786 - Axis Bank Ltd. CC Noida - GCF | H35: INR | I35: Creditors - GCF | J35: INR | K35: 34250 | L35: 1 | M35: 34250 | N35: 34250 | O35: 1 | P35: 34250 | Q35: Approved | R35: Initiated | S35: NEFT/RTGS | T35: Supplier | U35: Bajrang Traders | V35: Bajrang Traders | W35: 0 | X35: 0 | Y35: AXIS BANK 921030030087786 - NOIDA | AC35: -66628 | AD35: Bank | AE35: -4967967.3 | AF35: Payable | AG35: -66628 | AH35: 34250 | AI35: 34250 | AJ35: 34250 | AK35: 34250 | AL35: 0 | AM35: 0 | AN35: 34250 | AO35: 0 | AR35: 0 | AT35: 0 | AU35: 0 | AV35: G.C. Foods Pvt. Ltd. Noida - Uttar Pradesh (Shipping) | AW35: 09AACCG2244H1ZS | BB35: N/A | BC35: 45842 | BF35: Noida | BH35: Cancelled | BI35: 0 | BJ35: Amount INR 34250 to Bajrang Traders Transaction reference no N/A dated 2025-07-04 | BK35: INR Thirty Four Thousand, Two Hundred And Fifty only. | BL35: No | BO35: AXIS BANK | BP35: 921030030087786 | BR35: INR Thirty Four Thousand, Two Hundred And Fifty only. | BT35: Bajrang Traders
A36: PAY/N/25-26/0452 | B36: PAY/N/25-26/0452-1 | C36: PAY/G/23-24/.#### | D36: Pay | E36: 45842 | F36: G. C. Foods Pvt. Ltd. | G36: 921030030087786 - Axis Bank Ltd. CC Noida - GCF | H36: INR | I36: Creditors - GCF | J36: INR | K36: 1858.5 | L36: 1 | M36: 1858.5 | N36: 1858.5 | O36: 1 | P36: 1858.5 | Q36: Approved | R36: Initiated | S36: NEFT/RTGS | T36: Supplier | U36: AG Enviro Infra Projects Pvt Ltd. | V36: AG Enviro Infra Projects Pvt Ltd. | W36: 0 | X36: 0 | Y36: AXIS BANK 921030030087786 - NOIDA | AC36: 0 | AD36: Bank | AE36: -4966108.8 | AF36: Payable | AG36: 61392923 | AH36: 1858.5 | AI36: 1858.5 | AJ36: 1858.5 | AK36: 1858.5 | AL36: 0 | AM36: 0 | AN36: 1858.5 | AO36: 0 | AR36: 0 | AT36: 0 | AU36: 0 | AV36: G.C. Foods Pvt. Ltd. Noida - Uttar Pradesh (Shipping) | AW36: 09AACCG2244H1ZS | BB36: N/A | BC36: 45842 | BF36: Noida | BH36: Cancelled | BI36: 0 | BJ36: Amount INR 1858.5 to AG Enviro Infra Projects Pvt Ltd. Transaction reference no N/A dated 2025-07-04 | BK36: INR One Thousand, Eight Hundred And Fifty Eight and Fifty Paisa only. | BL36: No | BO36: AXIS BANK | BP36: 921030030087786 | BR36: INR One Thousand, Eight Hundred And Fifty Eight and Fifty Paisa only. | BT36: AG Enviro Infra Projects Pvt Ltd.
A37: PAY/N/25-26/0451 | B37: PAY/N/25-26/0451-1 | C37: PAY/G/23-24/.#### | D37: Pay | E37: 45842 | F37: G. C. Foods Pvt. Ltd. | G37: 921030030087786 - Axis Bank Ltd. CC Noida - GCF | H37: INR | I37: Creditors - GCF | J37: INR | K37: 9137.63 | L37: 1 | M37: 9137.63 | N37: 9137.63 | O37: 1 | P37: 9137.63 | Q37: Approved | R37: Initiated | S37: NEFT/RTGS | T37: Supplier | U37: DTDC Express Limited - Billing | V37: DTDC Express Limited | W37: 0 | X37: 0 | Y37: AXIS BANK 921030030087786 - NOIDA | AC37: 16376.93 | AD37: Bank | AE37: -4956971.2 | AF37: Payable | AG37: 16376.93 | AH37: 9137.63 | AI37: 9137.63 | AJ37: 9137.63 | AK37: 9137.63 | AL37: 0 | AM37: 0 | AN37: 9137.63 | AO37: 0 | AR37: 0 | AT37: 0 | AU37: 0 | AV37: G.C. Foods Pvt. Ltd. Noida - Uttar Pradesh (Shipping) | AW37: 09AACCG2244H1ZS | BB37: N/A | BC37: 45842 | BF37: Noida | BH37: Cancelled | BI37: 0 | BJ37: Amount INR 9137.63 to DTDC Express Limited Transaction reference no N/A dated 2025-07-04 | BK37: INR Nine Thousand, One Hundred And Thirty Seven and Sixty Three Paisa only. | BL37: No | BO37: AXIS BANK | BP37: 921030030087786 | BR37: INR Nine Thousand, One Hundred And Thirty Seven and Sixty Three Paisa only. | BT37: DTDC Express Limited
A38: PAY/N/25-26/0450 | B38: PAY/N/25-26/0450-1 | C38: PAY/G/23-24/.#### | D38: Pay | E38: 45842 | F38: G. C. Foods Pvt. Ltd. | G38: 921030030087786 - Axis Bank Ltd. CC Noida - GCF | H38: INR | I38: Creditors - GCF | J38: INR | K38: 27720 | L38: 1 | M38: 27720 | N38: 27720 | O38: 1 | P38: 27720 | Q38: Approved | R38: Initiated | S38: NEFT/RTGS | T38: Supplier | U38: Royal Securitas | V38: Royal Securitas | W38: 0 | X38: 0 | Y38: AXIS BANK 921030030087786 - NOIDA | AC38: 27720 | AD38: Bank | AE38: -4929251.2 | AF38: Payable | AG38: 27720 | AH38: 27720 | AI38: 27720 | AJ38: 27720 | AK38: 27720 | AL38: 0 | AM38: 0 | AN38: 27720 | AO38: 0 | AR38: 0 | AT38: 0 | AU38: 0 | AV38: G.C. Foods Pvt. Ltd. Noida - Uttar Pradesh (Shipping) | AW38: 09AACCG2244H1ZS | BB38: N/A | BC38: 45842 | BF38: Noida | BH38: Cancelled | BI38: 0 | BJ38: Amount INR 27720 to Royal Securitas Transaction reference no N/A dated 2025-07-04 | BK38: INR Twenty Seven Thousand, Seven Hundred And Twenty only. | BL38: No | BO38: AXIS BANK | BP38: 921030030087786 | BR38: INR Twenty Seven Thousand, Seven Hundred And Twenty only. | BT38: Royal Securitas
A39: PAY/G/25-26/1311 | B39: PAY/G/25-26/1311-1 | C39: PAY/G/23-24/.#### | D39: Pay | E39: 45850 | F39: G. C. Foods Pvt. Ltd. | G39: 9210300223943516 - Axis Bank Ltd. CC Tronica - GCF | H39: INR | I39: Creditors - GCF | J39: INR | K39: 45639 | L39: 1 | M39: 45639 | N39: 45639 | O39: 1 | P39: 45639 | Q39: Approved | R39: Initiated | S39: NEFT/RTGS | T39: Supplier | U39: GC foods Pvt Ltd Bihar | V39: GC foods Pvt Ltd Bihar | W39: 0 | X39: 0 | Y39: AXIS BANK 921030023943516 - GZB | AC39: 5195000 | AD39: Bank | AE39: -53344451 | AF39: Payable | AG39: 5195000 | AH39: 45639 | AI39: 45639 | AJ39: 45639 | AK39: 45639 | AL39: 0 | AM39: 0 | AN39: 45639 | AO39: 0 | AR39: 0 | AT39: 0 | AU39: 0 | AV39: G.C. Foods Pvt. Ltd.Ghaziabad - Uttar Pradesh-Billing | AW39: 09AACCG2244H1ZS | BB39: N/A | BC39: 45850 | BF39: Ghaziabad | BH39: Cancelled | BI39: 0 | BJ39: Amount INR 45639 to GC foods Pvt Ltd Bihar Transaction reference no N/A dated 2025-07-12 | BK39: INR Forty Five Thousand, Six Hundred And Thirty Nine only. | BL39: No | BO39: AXIS BANK | BP39: 921030023943516 | BR39: INR Forty Five Thousand, Six Hundred And Thirty Nine only. | BT39: GC foods Pvt Ltd Bihar
A40: PAY/G/25-26/1253 | B40: PAY/G/25-26/1253-1 | C40: PAY/G/23-24/.#### | D40: Pay | E40: 45848 | F40: G. C. Foods Pvt. Ltd. | G40: 9210300223943516 - Axis Bank Ltd. CC Tronica - GCF | H40: INR | I40: Creditors - GCF | J40: INR | K40: 620465.46 | L40: 1 | M40: 620465.46 | N40: 620465.46 | O40: 1 | P40: 620465.46 | Q40: Approved | R40: Initiated | S40: NEFT/RTGS | T40: Supplier | U40: Mahaadev Traders | V40: Mahaadev Traders | W40: 0 | X40: 0 | Y40: AXIS BANK 921030023943516 - GZB | AC40: 576960.12 | AD40: Bank | AE40: -53513900 | AF40: Payable | AG40: 576960.12 | AH40: 620465.46 | AI40: 620465.46 | AJ40: 620465.46 | AK40: 620465.46 | AL40: 0 | AM40: 0 | AN40: 620465.46 | AO40: 0 | AR40: 0 | AT40: 0 | AU40: 0 | AV40: G.C. Foods Pvt. Ltd.Ghaziabad - Uttar Pradesh-Billing | AW40: 09AACCG2244H1ZS | BB40: N/A | BC40: 45848 | BF40: Ghaziabad | BH40: Cancelled | BI40: 0 | BJ40: Amount INR 620465.46 to Mahaadev Traders Transaction reference no N/A dated 2025-07-10 | BK40: INR Six Lakh, Twenty Thousand, Four Hundred And Sixty Five and Forty Six Paisa only. | BL40: No | BO40: AXIS BANK | BP40: 921030023943516 | BR40: INR Six Lakh, Twenty Thousand, Four Hundred And Sixty Five and Forty Six Paisa only. | BT40: Mahaadev Traders
...

Sheet Old Status
A1: Sr | B1: ID | C1: Status | D1: docstatus | E1: Payment Type | F1: Posting Date | G1: Mode of Payment | H1: Party Type | I1: Party | J1: owner
A2: 1 | B2: PAY/G/25-26/1502-1 | C2: Submitted | D2: 1 | E2: Pay | F2: 45867 | G2: NEFT/RTGS | H2: Supplier | I2: Harish C. Khosla & Co. | J2: umagoswami77@gmail.com
A3: 2 | B3: PAY/G/25-26/1502 | C3: Cancelled | D3: 2 | E3: Pay | F3: 45867 | G3: NEFT/RTGS | H3: Supplier | I3: Harish C. Khosla & Co. | J3: umagoswami77@gmail.com
A4: 3 | B4: PAY/G/25-26/1507 | C4: Submitted | D4: 1 | E4: Pay | F4: 45867 | G4: NEFT/RTGS | H4: Employee | I4: Tanveeer Painter (T) | J4: umagoswami77@gmail.com
A5: 4 | B5: PAY/G/25-26/1506 | C5: Submitted | D5: 1 | E5: Pay | F5: 45867 | G5: NEFT/RTGS | H5: Supplier | I5: Blue Sky Cargo Movers | J5: umagoswami77@gmail.com
A6: 5 | B6: PAY/G/25-26/1505 | C6: Submitted | D6: 1 | E6: Pay | F6: 45867 | G6: NEFT/RTGS | H6: Supplier | I6: Ashu Communications | J6: umagoswami77@gmail.com
A7: 6 | B7: PAY/G/25-26/1504 | C7: Submitted | D7: 1 | E7: Pay | F7: 45867 | G7: NEFT/RTGS | H7: Supplier | I7: Victoria Foods Pvt. Ltd | J7: umagoswami77@gmail.com
A8: 7 | B8: PAY/G/25-26/1503 | C8: Submitted | D8: 1 | E8: Pay | F8: 45867 | G8: NEFT/RTGS | H8: Supplier | I8: Marudhara Polypack Industries | J8: umagoswami77@gmail.com
A9: 8 | B9: PAY/G/25-26/1501 | C9: Submitted | D9: 1 | E9: Pay | F9: 45867 | G9: NEFT/RTGS | H9: Supplier | I9: Genesis Pro Pac | J9: umagoswami77@gmail.com
A10: 9 | B10: PAY/G/25-26/1500 | C10: Submitted | D10: 1 | E10: Pay | F10: 45867 | G10: NEFT/RTGS | H10: Supplier | I10: Genesis Pro Pac | J10: umagoswami77@gmail.com
A11: 10 | B11: PAY/G/25-26/1499 | C11: Submitted | D11: 1 | E11: Pay | F11: 45867 | G11: NEFT/RTGS | H11: Supplier | I11: Genesis Pro Pac | J11: umagoswami77@gmail.com
A12: 11 | B12: PAY/G/25-26/1498 | C12: Submitted | D12: 1 | E12: Pay | F12: 45867 | G12: NEFT/RTGS | H12: Supplier | I12: Genesis Pro Pac | J12: umagoswami77@gmail.com
A13: 12 | B13: PAY/G/25-26/1497 | C13: Submitted | D13: 1 | E13: Pay | F13: 45867 | G13: NEFT/RTGS | H13: Supplier | I13: Gufa Overseas | J13: umagoswami77@gmail.com
... A46: 45 | B46: PAY/G/25-26/1478 | C46: Submitted | D46: 1 | E46: Receive | F46: 45866 | G46: NEFT/RTGS | H46: Customer | I46: krishan Dairy - Barola | J46: umagoswami77@gmail.com
A47: 46 | B47: PAY/G/25-26/1477 | C47: Submitted | D47: 1 | E47: Internal Transfer | F47: 45864 | G47: NEFT/RTGS | J47: umagoswami77@gmail.com
A48: 47 | B48: PAY/G/25-26/1476 | C48: Submitted | D48: 1 | E48: Receive | F48: 45864 | G48: NEFT/RTGS | H48: Customer | I48: Shree Shyam Traders | J48: umagoswami77@gmail.com
A49: 48 | B49: PAY/N/25-26/0577 | C49: Submitted | D49: 1 | E49: Pay | F49: 45863 | G49: NEFT/RTGS | H49: Supplier | I49: CASH ROJNAMCHA NOIDA | J49: umagoswami77@gmail.com
A50: 49 | B50: PAY/N/25-26/0576 | C50: Submitted | D50: 1 | E50: Pay | F50: 45863 | G50: NEFT/RTGS | H50: Employee | I50: Lal Babu - Staff Operator | J50: umagoswami77@gmail.com
A51: 50 | B51: PAY/N/25-26/0575 | C51: Submitted | D51: 1 | E51: Pay | F51: 45863 | G51: NEFT/RTGS | H51: Supplier | I51: Woxan Packaging Solutions Pvt Ltd | J51: umagoswami77@gmail.com
A52: 51 | B52: PAY/M/25-26/0928 | C52: Submitted | D52: 1 | E52: Pay | F52: 45863 | G52: NEFT/RTGS | H52: Supplier | I52: Steel Centre | J52: umagoswami77@gmail.com
A53: 52 | B53: PAY/M/25-26/0927 | C53: Submitted | D53: 1 | E53: Receive | F53: 45863 | G53: NEFT/RTGS | H53: Customer | I53: G.C.Wilmar Private Limited | J53: umagoswami77@gmail.com
A54: 53 | B54: PAY/M/25-26/0926 | C54: Submitted | D54: 1 | E54: Pay | F54: 45862 | G54: NEFT/RTGS | H54: Supplier | I54: Dev Shri Road Line | J54: umagoswami77@gmail.com
A55: 54 | B55: PAY/M/25-26/0925 | C55: Submitted | D55: 1 | E55: Pay | F55: 45862 | G55: NEFT/RTGS | H55: Supplier | I55: Mansaka Transport Company | J55: umagoswami77@gmail.com
A56: 55 | B56: PAY/M/25-26/0924 | C56: Submitted | D56: 1 | E56: Receive | F56: 45862 | G56: NEFT/RTGS | H56: Customer | I56: G.C.Wilmar Private Limited | J56: umagoswami77@gmail.com
A57: 56 | B57: PAY/M/25-26/0911 | C57: Cancelled | D57: 2 | E57: Receive | F57: 45861 | G57: NEFT/RTGS | H57: Customer | I57: G.C.Wilmar Private Limited | J57: juliemandal96@gmail.com
A58: 57 | B58: PAY/M/25-26/0913 | C58: Submitted | D58: 1 | E58: Pay | F58: 45861 | G58: NEFT/RTGS | H58: Supplier | I58: Prakash Pipes Limited | J58: juliemandal96@gmail.com
A59: 58 | B59: PAY/M/25-26/0912 | C59: Submitted | D59: 1 | E59: Pay | F59: 45861 | G59: NEFT/RTGS | H59: Supplier | I59: Shiv Vegpro Pvt Ltd | J59: juliemandal96@gmail.com
... A66: 65 | B66: PAY/G/25-26/1474 | C66: Submitted | D66: 1 | E66: Pay | F66: 45863 | G66: NEFT/RTGS | H66: Supplier | I66: Amit Enterprises | J66: umagoswami77@gmail.com
A67: 66 | B67: PAY/G/25-26/1473 | C67: Submitted | D67: 1 | E67: Internal Transfer | F67: 45863 | G67: NEFT/RTGS | J67: umagoswami77@gmail.com
A68: 67 | B68: PAY/G/25-26/1472 | C68: Submitted | D68: 1 | E68: Receive | F68: 45863 | G68: NEFT/RTGS | H68: Customer | I68: Narendra Traders | J68: umagoswami77@gmail.com
A69: 68 | B69: PAY/G/25-26/1471 | C69: Submitted | D69: 1 | E69: Receive | F69: 45863 | G69: NEFT/RTGS | H69: Customer | I69: Maheshwari Sales Agency | J69: umagoswami77@gmail.com
A70: 69 | B70: PAY/G/25-26/1470 | C70: Submitted | D70: 1 | E70: Receive | F70: 45863 | G70: NEFT/RTGS | H70: Customer | I70: A R Traders | J70: umagoswami77@gmail.com
A71: 70 | B71: PAY/G/25-26/1469 | C71: Submitted | D71: 1 | E71: Receive | F71: 45863 | G71: NEFT/RTGS | H71: Customer | I71: RRR Traders | J71: umagoswami77@gmail.com
A72: 71 | B72: PAY/G/25-26/1468 | C72: Submitted | D72: 1 | E72: Receive | F72: 45863 | G72: NEFT/RTGS | H72: Customer | I72: RRR Traders | J72: umagoswami77@gmail.com
A73: 72 | B73: PAY/G/25-26/1467 | C73: Submitted | D73: 1 | E73: Receive | F73: 45863 | G73: NEFT/RTGS | H73: Customer | I73: Saawariya Trading Company | J73: umagoswami77@gmail.com
A74: 73 | B74: PAY/G/25-26/1466 | C74: Submitted | D74: 1 | E74: Receive | F74: 45863 | G74: NEFT/RTGS | H74: Customer | I74: Abhishek Trading Co. | J74: umagoswami77@gmail.com
A75: 74 | B75: PAY/G/25-26/1465 | C75: Submitted | D75: 1 | E75: Receive | F75: 45863 | G75: NEFT/RTGS | H75: Customer | I75: Gita Agency | J75: umagoswami77@gmail.com
A76: 75 | B76: PAY/G/25-26/1464 | C76: Submitted | D76: 1 | E76: Receive | F76: 45863 | G76: NEFT/RTGS | H76: Customer | I76: Vardhman Cattle Feed | J76: umagoswami77@gmail.com
A77: 76 | B77: PAY/N/25-26/0574 | C77: Submitted | D77: 1 | E77: Receive | F77: 45859 | G77: NEFT/RTGS | H77: Customer | I77: Amazon Courier | J77: umagoswami77@gmail.com
A78: 77 | B78: PAY/N/25-26/0554-1 | C78: Submitted | D78: 1 | E78: Receive | F78: 45848 | G78: NEFT/RTGS | H78: Customer | I78: E-powertech | J78: umagoswami77@gmail.com
...

Sheet Payment Entry Working
A1: Amended From | B1: ID | C1: Old Status | D1: Series | E1: Payment Type | F1: Posting Date | G1: Company | H1: Account Paid From | I1: Account Currency (From) | J1: Account Paid To | K1: Account Currency (To) | L1: Paid Amount | M1: Source Exchange Rate | N1: Paid Amount (Company Currency) | O1: Received Amount | P1: Target Exchange Rate | Q1: Received Amount (Company Currency) | R1: Workflow State | S1: Payment Order Status | T1: Mode of Payment | U1: Party Type | V1: Party | W1: Party Name | X1: Book Advance Payments in Separate Party Account | Y1: Reconcile on Advance Payment Date | Z1: Company Bank Account | AA1: Party Bank Account | AB1: Contact | AC1: Email | AD1: Party Balance | AE1: Paid From Account Type | AF1: Account Balance (From) | AG1: Paid To Account Type | AH1: Account Balance (To) | AI1: Paid Amount After Tax | AJ1: Paid Amount After Tax (Company Currency) | AK1: Received Amount After Tax | AL1: Received Amount After Tax (Company Currency) | AM1: Total Allocated Amount | AN1: Total Allocated Amount (Company Currency) | AO1: Unallocated Amount | AP1: Difference Amount (Company Currency) | AQ1: Purchase Taxes and Charges Template | AR1: Sales Taxes and Charges Template | AS1: Apply Tax Withholding Amount | AT1: Tax Withholding Category | AU1: Total Taxes and Charges (Company Currency) | AV1: Total Taxes and Charges | AW1: Company Address | AX1: Company GSTIN | AY1: Place of Supply | AZ1: Customer Address | BA1: Customer GSTIN | BB1: GST Category | BC1: Cheque/Reference No | BD1: Cheque/Reference Date | BE1: Clearance Date | BF1: Project | BG1: Branch | BH1: Cost Center | BI1: Status | BJ1: Custom Remarks | BK1: Remarks | BL1: In Words (Company Currency) | BM1: Is Opening | BN1: Letter Head | BO1: Print Heading | BP1: Bank | BQ1: Bank Account No | BR1: Payment Order | BS1: In Words | BT1: Auto Repeat | BU1: Title | BV1: ID (Payment References) | BW1: Account (Payment References) | BX1: Account Type (Payment References) | BY1: Allocated (Payment References) | BZ1: Due Date (Payment References) | CA1: Exchange Gain/Loss (Payment References) | CB1: Exchange Rate (Payment References) | CC1: Grand Total (Payment References) | CD1: Name (Payment References) | CE1: Outstanding (Payment References) | CF1: Payment Request (Payment References) | CG1: Payment Term (Payment References) | CH1: Payment Term Outstanding (Payment References) | CI1: Payment Type (Payment References) | CJ1: Reconcile Effect On (Payment References) | CK1: Supplier Invoice No (Payment References) | CL1: Type (Payment References) | CM1: ID (Advance Taxes and Charges) | CN1: Account Currency (Advance Taxes and Charges) | CO1: Account Head (Advance Taxes and Charges) | CP1: Add Or Deduct (Advance Taxes and Charges) | CQ1: Allocated Amount (Advance Taxes and Charges) | CR1: Amount (Advance Taxes and Charges) | CS1: Amount (Company Currency) (Advance Taxes and Charges) | CT1: Considered In Paid Amount (Advance Taxes and Charges) | CU1: Cost Center (Advance Taxes and Charges) | CV1: Description (Advance Taxes and Charges) | CW1: GST Tax Type (Advance Taxes and Charges) | CX1: Reference Row # (Advance Taxes and Charges) | CY1: Tax Rate (Advance Taxes and Charges) | CZ1: Total (Advance Taxes and Charges) | DA1: Total (Company Currency) (Advance Taxes and Charges) | DB1: Type (Advance Taxes and Charges) | DC1: ID (Payment Deductions or Loss) | DD1: Account (Payment Deductions or Loss) | DE1: Amount (Company Currency) (Payment Deductions or Loss) | DF1: Branch (Payment Deductions or Loss) | DG1: Cost Center (Payment Deductions or Loss) | DH1: Description (Payment Deductions or Loss) | DI1: Is Exchange Gain / Loss? (Payment Deductions or Loss)
