Workbook

Sheet Purchase Invoice Raw
A1: Amended From | B1: ID | C1: Series | D1: Supplier | E1: Date | F1: Branch | G1: Credit To | H1: Title | I1: Supplier Name | J1: e-Waybill No. | K1: Tax Id | L1: Company | M1: Posting Time | N1: Edit Posting Date and Time | O1: Due Date | P1: Purchase Order Type | Q1: Is Paid | R1: Is Return (Debit Note) | S1: Return Against Purchase Invoice | T1: Update Outstanding for Self | U1: Update Billed Amount in Purchase Order | V1: Update Billed Amount in Purchase Receipt | W1: Apply Tax Withholding Amount | X1: Is Reverse Charge | Y1: Tax Withholding Category | Z1: Supplier Invoice No | AA1: Supplier Invoice Date | AB1: Cost Center | AC1: Project | AD1: Currency | AE1: Exchange Rate | AF1: Use Transaction Date Exchange Rate | AG1: Price List | AH1: Price List Currency | AI1: Price List Exchange Rate | AJ1: Ignore Pricing Rule | AK1: Scan Barcode | AL1: Update Stock | AM1: Set Accepted Warehouse | AN1: Set From Warehouse | AO1: Is Subcontracted | AP1: Rejected Warehouse | AQ1: Supplier Warehouse | AR1: Total Quantity | AS1: Total Net Weight | AT1: Total (Company Currency) | AU1: Net Total (Company Currency) | AV1: Total | AW1: Net Total | AX1: Tax Withholding Net Total | AY1: Base Tax Withholding Net Total | AZ1: Tax Category | BA1: Purchase Taxes and Charges Template | BB1: Shipping Rule | BC1: Incoterm | BD1: Named Place | BE1: Taxes and Charges Added (Company Currency) | BF1: Taxes and Charges Deducted (Company Currency) | BG1: Total Taxes and Charges (Company Currency) | BH1: Taxes and Charges Added | BI1: Taxes and Charges Deducted | BJ1: Total Taxes and Charges | BK1: Grand Total (Company Currency) | BL1: Rounding Adjustment (Company Currency) | BM1: Rounded Total (Company Currency) | BN1: In Words (Company Currency) | BO1: Grand Total | BP1: Rounding Adjustment | BQ1: Use Company Default Round Off Cost Center | BR1: Rounded Total | BS1: In Words | BT1: Total Advance | BU1: Outstanding Amount | BV1: Disable Rounded Total | BW1: Apply Additional Discount On | BX1: Additional Discount Amount (Company Currency) | BY1: Additional Discount Percentage | BZ1: Additional Discount Amount | CA1: Taxes and Charges Calculation | CB1: Mode of Payment | CC1: Paid Amount (Company Currency) | CD1: Clearance Date | CE1: Cash/Bank Account | CF1: Paid Amount | CG1: Set Advances and Allocate (FIFO) | CH1: Only Include Allocated Payments | CI1: Write Off Amount | CJ1: Write Off Amount (Company Currency) | CK1: Write Off Account | CL1: Write Off Cost Center | CM1: Select Supplier Address | CN1: Address | CO1: Supplier GSTIN | CP1: GST Category | CQ1: Contact Person | CR1: Contact | CS1: Mobile No | CT1: Contact Email | CU1: Select Dispatch Address | CV1: Dispatch Address | CW1: Select Shipping Address | CX1: Shipping Address | CY1: Select Billing Address | CZ1: Billing Address | DA1: Company GSTIN | DB1: Place of Supply | DC1: Payment Terms Template | DD1: Ignore Default Payment Terms Template | DE1: Terms | DF1: Terms and Conditions | DG1: Per Received | DH1: Party Account Currency | DI1: Is Opening Entry | DJ1: Against Expense Account | DK1: Unrealized Profit / Loss Account | DL1: Subscription | DM1: Auto Repeat | DN1: From Date | DO1: To Date | DP1: Letter Head | DQ1: Group same items | DR1: Print Heading | DS1: Print Language | DT1: Transporter | DU1: GST Transporter ID | DV1: Driver | DW1: Transport Receipt No | DX1: Vehicle No | DY1: Distance (in km) | DZ1: Transporter Name | EA1: Mode of Transport | EB1: Driver Name | EC1: Transport Receipt Date | ED1: GST Vehicle Type | EE1: ITC Classification | EF1: Reason for Ineligibility | EG1: Reconciliation Status | EH1: Hold Invoice | EI1: Release Date | EJ1: Reason For Putting On Hold | EK1: Is Internal Supplier | EL1: Represents Company | EM1: Supplier Group | EN1: Inter Company Invoice Reference | EO1: Is Old Subcontracting Flow | EP1: Remarks | EQ1: ID (Items) | ER1: Accepted Qty (Items) | ES1: Accepted Qty in Stock UOM (Items) | ET1: Amount (Items) | EU1: Amount (Company Currency) (Items) | EV1: Item Name (Items) | EW1: Rate (Items) | EX1: Rate (Company Currency) (Items) | EY1: UOM (Items) | EZ1: UOM Conversion Factor (Items) | FA1: Accepted Warehouse (Items) | FB1: Allow Zero Valuation Rate (Items) | FC1: Apply TDS (Items) | FD1: Asset Category (Items) | FE1: Asset Location (Items) | FF1: Batch No (Items) | FG1: BOM (Items) | FH1: Brand (Items) | FI1: CESS Amount (Items) | FJ1: CESS Non Advol Amount (Items) | FK1: CESS Non Advol Rate (Items) | FL1: CESS Rate (Items) | FM1: CGST Amount (Items) | FN1: CGST Rate (Items) | FO1: Cost Center (Items) | FP1: Deferred Expense Account (Items) | FQ1: Description (Items) | FR1: Discount Amount (Items) | FS1: Discount on Price List Rate (%) (Items) | FT1: Distributed Discount Amount (Items) | FU1: Enable Deferred Expense (Items) | FV1: Expense Head (Items) | FW1: From Warehouse (Items) | FX1: GST Treatment (Items) | FY1: HSN/SAC (Items) | FZ1: IGST Amount (Items) | GA1: IGST Rate (Items) | GB1: Image (Items) | GC1: Include Exploded Items (Items) | GD1: Is Fixed Asset (Items) | GE1: Is Free Item (Items) | GF1: Is Ineligible for Input Tax Credit (Items) | GG1: Item (Items) | GH1: Item Group (Items) | GI1: Item Tax Amount Included in Value (Items) | GJ1: Item Tax Rate (Items) | GK1: Item Tax Template (Items) | GL1: Landed Cost Voucher Amount (Items) | GM1: Manufacturer (Items) | GN1: Manufacturer Part Number (Items) | GO1: Margin Rate or Amount (Items) | GP1: Margin Type (Items) | GQ1: Material Request (Items) | GR1: Material Request Item (Items) | GS1: Net Amount (Items) | GT1: Net Amount (Company Currency) (Items) | GU1: Net Rate (Items) | GV1: Net Rate (Company Currency) (Items) | GW1: Page Break (Items) | GX1: Pending BOE Qty (Items) | GY1: Price List Rate (Items) | GZ1: Price List Rate (Company Currency) (Items) | HA1: Pricing Rules (Items) | HB1: Product Bundle (Items) | HC1: Project (Items) | HD1: Purchase Invoice Item (Items) | HE1: Purchase Order (Items) | HF1: Purchase Order Item (Items) | HG1: Purchase Receipt (Items) | HH1: Purchase Receipt Detail (Items) | HI1: Quality Inspection (Items) | HJ1: Rate of Stock UOM (Items) | HK1: Rate With Margin (Items) | HL1: Rate With Margin (Company Currency) (Items) | HM1: Raw Materials Supplied Cost (Items) | HN1: Received Qty (Items) | HO1: Rejected Branch (Items) | HP1: Rejected Qty (Items) | HQ1: Rejected Serial and Batch Bundle (Items) | HR1: Rejected Serial No (Items) | HS1: Rejected Warehouse (Items) | HT1: Sales Incoming Rate (Items) | HU1: Sales Invoice Item (Items) | HV1: Serial and Batch Bundle (Items) | HW1: Serial No (Items) | HX1: Service End Date (Items) | HY1: Service Start Date (Items) | HZ1: Service Stop Date (Items) | IA1: SGST Amount (Items) | IB1: SGST Rate (Items) | IC1: Source Branch (Items) | ID1: Stock UOM (Items) | IE1: Target Branch (Items) | IF1: Taxable Value (Items) | IG1: Total Weight (Items) | IH1: Use Serial No / Batch Fields (Items) | II1: Valuation Rate (Items) | IJ1: Weight Per Unit (Items) | IK1: Weight UOM (Items) | IL1: WIP Composite Asset (Items) | IM1: ID (Purchase Taxes and Charges) | IN1: Account Currency (Purchase Taxes and Charges) | IO1: Account Head (Purchase Taxes and Charges) | IP1: Add or Deduct (Purchase Taxes and Charges) | IQ1: Amount (Purchase Taxes and Charges) | IR1: Amount (Company Currency) (Purchase Taxes and Charges) | IS1: Branch (Purchase Taxes and Charges) | IT1: Consider Tax or Charge for (Purchase Taxes and Charges) | IU1: Considered In Paid Amount (Purchase Taxes and Charges) | IV1: Cost Center (Purchase Taxes and Charges) | IW1: Description (Purchase Taxes and Charges) | IX1: GST Tax Type (Purchase Taxes and Charges) | IY1: Is Tax Withholding Account (Purchase Taxes and Charges) | IZ1: Is this Tax included in Basic Rate? (Purchase Taxes and Charges) | JA1: Item Wise Tax Detail (Purchase Taxes and Charges) | JB1: Reference Row # (Purchase Taxes and Charges) | JC1: Tax Amount After Discount Amount (Purchase Taxes and Charges) | JD1: taxes.base_tax_amount_after_discount_amount | JE1: Tax Rate (Purchase Taxes and Charges) | JF1: Total (Purchase Taxes and Charges) | JG1: Total (Company Currency) (Purchase Taxes and Charges) | JH1: Type (Purchase Taxes and Charges) | JI1: ID (Tax Withheld Vouchers) | JJ1: Taxable Amount (Tax Withheld Vouchers) | JK1: Voucher Name (Tax Withheld Vouchers) | JL1: Voucher Type (Tax Withheld Vouchers) | JM1: ID (Pricing Rule Detail) | JN1: Child Docname (Pricing Rule Detail) | JO1: Item Code (Pricing Rule Detail) | JP1: Margin Type (Pricing Rule Detail) | JQ1: Pricing Rule (Pricing Rule Detail) | JR1: Rate or Discount (Pricing Rule Detail) | JS1: Rule Applied (Pricing Rule Detail) | JT1: ID (Supplied Items) | JU1: Amount (Supplied Items) | JV1: Available Qty For Consumption (Supplied Items) | JW1: Batch No (Supplied Items) | JX1: BOM Detail No (Supplied Items) | JY1: Branch (Supplied Items) | JZ1: Conversion Factor (Supplied Items) | KA1: Current Stock (Supplied Items) | KB1: Description (Supplied Items) | KC1: Item Code (Supplied Items) | KD1: Item Name (Supplied Items) | KE1: Purchase Order (Supplied Items) | KF1: Qty to Be Consumed (Supplied Items) | KG1: Rate (Supplied Items) | KH1: Raw Material Item Code (Supplied Items) | KI1: Reference Name (Supplied Items) | KJ1: Serial No (Supplied Items) | KK1: Stock Uom (Supplied Items) | KL1: ID (Advances) | KM1: Advance Amount (Advances) | KN1: Allocated Amount (Advances) | KO1: Difference Posting Date (Advances) | KP1: Exchange Gain/Loss (Advances) | KQ1: Reference Exchange Rate (Advances) | KR1: Reference Name (Advances) | KS1: Reference Row (Advances) | KT1: Reference Type (Advances) | KU1: Remarks (Advances) | KV1: ID (Advance Tax) | KW1: Account Head (Advance Tax) | KX1: Allocated Amount (Advance Tax) | KY1: Reference Detail (Advance Tax) | KZ1: Reference Name (Advance Tax) | LA1: Reference Type (Advance Tax) | LB1: ID (Payment Schedule) | LC1: Description (Payment Schedule) | LD1: Discount (Payment Schedule) | LE1: Discount Date (Payment Schedule) | LF1: Discount Type (Payment Schedule) | LG1: Discounted Amount (Payment Schedule) | LH1: Due Date (Payment Schedule) | LI1: Invoice Portion (Payment Schedule) | LJ1: Mode of Payment (Payment Schedule) | LK1: Outstanding (Payment Schedule) | LL1: Outstanding (Company Currency) (Payment Schedule) | LM1: Paid Amount (Payment Schedule) | LN1: Paid Amount (Company Currency) (Payment Schedule) | LO1: Payment Amount (Payment Schedule) | LP1: Payment Amount (Company Currency) (Payment Schedule) | LQ1: Payment Term (Payment Schedule)
A2: PI/G/25-26/0202 | B2: PI/G/25-26/0202-1 | C2: PINV-.YY.- | D2: Freight Outward Non TDS | E2: 45759 | F2: Ghaziabad | G2: Creditors - GCF | H2: Freight Outward Non TDS | I2: Freight Outward Non TDS | L2: G. C. Foods Pvt. Ltd. | M2: 0.63431713 | N2: 1 | O2: 45759 | Q2: 0 | R2: 0 | T2: 1 | U2: 0 | V2: 1 | W2: 0 | X2: 1 | AD2: INR | AE2: 1 | AF2: 1 | AG2: Standard Buying | AH2: INR | AI2: 1 | AJ2: 0 | AL2: 0 | AO2: 0 | AR2: 1 | AS2: 0 | AT2: 40000 | AU2: 40000 | AV2: 40000 | AW2: 40000 | AX2: 40000 | AY2: 40000 | BA2: Input GST RCM In-state - GCF | BE2: 2000 | BF2: 2000 | BG2: 0 | BH2: 2000 | BI2: 2000 | BJ2: 0 | BK2: 40000 | BL2: 0 | BM2: 0 | BN2: INR Forty Thousand only. | BO2: 40000 | BP2: 0 | BQ2: 0 | BR2: 0 | BS2: INR Forty Thousand only. | BT2: 0 | BU2: 40000 | BV2: 1 | BW2: Grand Total | BX2: 0 | BY2: 0 | BZ2: 0 | CA2: | HSN/SAC | Taxable Amount | Input Tax CGST @ 9.0 | Input Tax SGST @ 9.0 | Input Tax CGST RCM @ 9.0 | Input Tax SGST RCM @ 9.0 | | --- | --- | --- | --- | --- | --- | | 996511 | ₹ 40,000.00 | (2.5%) ₹ 1,000.00 | (2.5%) ₹ 1,000.00 | (2.5%) ₹ 1,000.00 | (2.5%) ₹ 1,000.00 | | CC2: 0 | CF2: 0 | CG2: 0 | CH2: 0 | CI2: 0 | CJ2: 0 | CP2: Unregistered | CW2: G.C. Foods Pvt. Ltd.Ghaziabad - Uttar Pradesh-Billing | CX2: C-4, Sector A-2, , Tronica city Indl. Area, LoniGhaziabad, Uttar Pradesh, State Code: 09, Pincode: 201103, India, Phone: 9350041990, GSTIN: 09AACCG2244H1ZS, | CY2: G.C. Foods Pvt. Ltd.Ghaziabad - Uttar Pradesh-Billing | CZ2: C-4, Sector A-2, , Tronica city Indl. Area, LoniGhaziabad, Uttar Pradesh, State Code: 09, Pincode: 201103, India, Phone: 9350041990, GSTIN: 09AACCG2244H1ZS, | DA2: 09AACCG2244H1ZS | DB2: 09-Uttar Pradesh | DD2: 0 | DG2: 0 | DH2: INR | DI2: No | DJ2: Freight Outward - GCF | DP2: GCF Letterhead | DQ2: 0 | DS2: en | DY2: 0 | EA2: Road | EC2: 45869 | ED2: Regular | EE2: ITC on Reverse Charge | EG2: Not Applicable | EH2: 0 | EK2: 0 | EM2: Creditors (Transport) | EO2: 0 | EP2: No Remarks | ER2: 1 | ES2: 1 | ET2: 40000 | EU2: 40000 | EV2: Freight Outward - GCF | EW2: 40000 | EX2: 40000 | EY2: Unit | EZ2: 1 | FB2: 0 | FC2: 1 | FI2: 0 | FJ2: 0 | FK2: 0 | FL2: 0 | FM2: 1000 | FN2: 2.5 | FO2: Main - GCF | FQ2: Freight Outward | FR2: 0 | FS2: 0 | FT2: 0 | FU2: 0 | FV2: Freight Outward - GCF | FX2: Taxable | FY2: 996511 | FZ2: 0 | GA2: 0 | GC2: 0 | GD2: 0 | GE2: 0 | GF2: 0 | GG2: Freight Outward - GCF | GH2: Services | GI2: 0 | GJ2: {"Output Tax SGST - GCF": 2.5, "Output Tax CGST - GCF": 2.5, "Output Tax IGST - GCF": 5.0, "Input Tax SGST - GCF": 2.5, "Input Tax CGST - GCF": 2.5, "Input Tax IGST - GCF": 5.0, "Input Tax SGST RCM - GCF": 2.5, "Input Tax CGST RCM - GCF": 2.5, "Input Tax IGST RCM - GCF": 5.0} | GK2: GST 5% - GCF | GL2: 0 | GO2: 0 | GS2: 40000 | GT2: 40000 | GU2: 40000 | GV2: 40000 | GW2: 0 | GX2: 1 | GY2: 0 | GZ2: 0 | HJ2: 40000 | HK2: 0 | HL2: 0 | HM2: 0 | HN2: 0 | HP2: 0 | HT2: 0 | IA2: 1000 | IB2: 2.5 | ID2: Unit | IE2: Ghaziabad | IF2: 40000 | IG2: 0 | IH2: 0 | II2: 0 | IJ2: 0 | IN2: INR | IO2: Input Tax CGST - GCF | IP2: Add | IQ2: 1000 | IR2: 1000 | IT2: Total | IU2: 0 | IV2: Main - GCF | IW2: Input Tax CGST @ 9.0 | IX2: cgst | IY2: 0 | IZ2: 0 | JA2: {"Freight Outward - GCF":[2.5,1000.0]} | JC2: 1000 | JD2: 1000 | JE2: 0 | JF2: 41000 | JG2: 41000 | JH2: On Net Total | LD2: 0 | LG2: 0 | LH2: 45759 | LI2: 100 | LK2: 40000 | LL2: 40000 | LM2: 0 | LN2: 0 | LO2: 40000 | LP2: 40000
IN3: INR | IO3: Input Tax SGST - GCF | IP3: Add | IQ3: 1000 | IR3: 1000 | IT3: Total | IU3: 0 | IV3: Main - GCF | IW3: Input Tax SGST @ 9.0 | IX3: sgst | IY3: 0 | IZ3: 0 | JA3: {"Freight Outward - GCF":[2.5,1000.0]} | JC3: 1000 | JD3: 1000 | JE3: 0 | JF3: 42000 | JG3: 42000 | JH3: On Net Total
IN4: INR | IO4: Input Tax CGST RCM - GCF | IP4: Deduct | IQ4: 1000 | IR4: 1000 | IT4: Total | IU4: 0 | IV4: Main - GCF | IW4: Input Tax CGST RCM @ 9.0 | IX4: cgst_rcm | IY4: 0 | IZ4: 0 | JA4: {"Freight Outward - GCF":[2.5,1000.0]} | JC4: 1000 | JD4: 1000 | JE4: 0 | JF4: 41000 | JG4: 41000 | JH4: On Net Total
IN5: INR | IO5: Input Tax SGST RCM - GCF | IP5: Deduct | IQ5: 1000 | IR5: 1000 | IT5: Total | IU5: 0 | IV5: Main - GCF | IW5: Input Tax SGST RCM @ 9.0 | IX5: sgst_rcm | IY5: 0 | IZ5: 0 | JA5: {"Freight Outward - GCF":[2.5,1000.0]} | JC5: 1000 | JD5: 1000 | JE5: 0 | JF5: 40000 | JG5: 40000 | JH5: On Net Total
A6: PI/G/25-26/0201 | B6: PI/G/25-26/0201-1 | C6: PINV-.YY.- | D6: Freight Outward Non TDS | E6: 45749 | F6: Ghaziabad | G6: Creditors - GCF | H6: Freight Outward Non TDS | I6: Freight Outward Non TDS | L6: G. C. Foods Pvt. Ltd. | M6: 0.63162037 | N6: 1 | O6: 45749 | Q6: 0 | R6: 0 | T6: 1 | U6: 0 | V6: 1 | W6: 0 | X6: 1 | AD6: INR | AE6: 1 | AF6: 1 | AG6: Standard Buying | AH6: INR | AI6: 1 | AJ6: 0 | AL6: 0 | AO6: 0 | AR6: 1 | AS6: 0 | AT6: 50000 | AU6: 50000 | AV6: 50000 | AW6: 50000 | AX6: 50000 | AY6: 50000 | BA6: Input GST RCM In-state - GCF | BE6: 2500 | BF6: 2500 | BG6: 0 | BH6: 2500 | BI6: 2500 | BJ6: 0 | BK6: 50000 | BL6: 0 | BM6: 0 | BN6: INR Fifty Thousand only. | BO6: 50000 | BP6: 0 | BQ6: 0 | BR6: 0 | BS6: INR Fifty Thousand only. | BT6: 0 | BU6: 50000 | BV6: 1 | BW6: Grand Total | BX6: 0 | BY6: 0 | BZ6: 0 | CA6: | HSN/SAC | Taxable Amount | Input Tax CGST @ 9.0 | Input Tax SGST @ 9.0 | Input Tax CGST RCM @ 9.0 | Input Tax SGST RCM @ 9.0 | | --- | --- | --- | --- | --- | --- | | 996511 | ₹ 50,000.00 | (2.5%) ₹ 1,250.00 | (2.5%) ₹ 1,250.00 | (2.5%) ₹ 1,250.00 | (2.5%) ₹ 1,250.00 | | CC6: 0 | CF6: 0 | CG6: 0 | CH6: 0 | CI6: 0 | CJ6: 0 | CP6: Unregistered | CW6: G.C. Foods Pvt. Ltd.Ghaziabad - Uttar Pradesh-Billing | CX6: C-4, Sector A-2, , Tronica city Indl. Area, LoniGhaziabad, Uttar Pradesh, State Code: 09, Pincode: 201103, India, Phone: 9350041990, GSTIN: 09AACCG2244H1ZS, | CY6: G.C. Foods Pvt. Ltd.Ghaziabad - Uttar Pradesh-Billing | CZ6: C-4, Sector A-2, , Tronica city Indl. Area, LoniGhaziabad, Uttar Pradesh, State Code: 09, Pincode: 201103, India, Phone: 9350041990, GSTIN: 09AACCG2244H1ZS, | DA6: 09AACCG2244H1ZS | DB6: 09-Uttar Pradesh | DD6: 0 | DG6: 0 | DH6: INR | DI6: No | DJ6: Freight Outward - GCF | DP6: GCF Letterhead | DQ6: 0 | DS6: en | DY6: 0 | EA6: Road | EC6: 45869 | ED6: Regular | EE6: ITC on Reverse Charge | EG6: Not Applicable | EH6: 0 | EK6: 0 | EM6: Creditors (Transport) | EO6: 0 | EP6: No Remarks | ER6: 1 | ES6: 1 | ET6: 50000 | EU6: 50000 | EV6: Freight Outward - GCF | EW6: 50000 | EX6: 50000 | EY6: Unit | EZ6: 1 | FB6: 0 | FC6: 1 | FI6: 0 | FJ6: 0 | FK6: 0 | FL6: 0 | FM6: 1250 | FN6: 2.5 | FO6: Main - GCF | FQ6: Freight Outward | FR6: 0 | FS6: 0 | FT6: 0 | FU6: 0 | FV6: Freight Outward - GCF | FX6: Taxable | FY6: 996511 | FZ6: 0 | GA6: 0 | GC6: 0 | GD6: 0 | GE6: 0 | GF6: 0 | GG6: Freight Outward - GCF | GH6: Services | GI6: 0 | GJ6: {"Output Tax SGST - GCF": 2.5, "Output Tax CGST - GCF": 2.5, "Output Tax IGST - GCF": 5.0, "Input Tax SGST - GCF": 2.5, "Input Tax CGST - GCF": 2.5, "Input Tax IGST - GCF": 5.0, "Input Tax SGST RCM - GCF": 2.5, "Input Tax CGST RCM - GCF": 2.5, "Input Tax IGST RCM - GCF": 5.0} | GK6: GST 5% - GCF | GL6: 0 | GO6: 0 | GS6: 50000 | GT6: 50000 | GU6: 50000 | GV6: 50000 | GW6: 0 | GX6: 1 | GY6: 0 | GZ6: 0 | HJ6: 50000 | HK6: 0 | HL6: 0 | HM6: 0 | HN6: 0 | HP6: 0 | HT6: 0 | IA6: 1250 | IB6: 2.5 | ID6: Unit | IE6: Ghaziabad | IF6: 50000 | IG6: 0 | IH6: 0 | II6: 0 | IJ6: 0 | IN6: INR | IO6: Input Tax CGST - GCF | IP6: Add | IQ6: 1250 | IR6: 1250 | IT6: Total | IU6: 0 | IV6: Main - GCF | IW6: Input Tax CGST @ 9.0 | IX6: cgst | IY6: 0 | IZ6: 0 | JA6: {"Freight Outward - GCF":[2.5,1250.0]} | JC6: 1250 | JD6: 1250 | JE6: 0 | JF6: 51250 | JG6: 51250 | JH6: On Net Total | LD6: 0 | LG6: 0 | LH6: 45749 | LI6: 100 | LK6: 50000 | LL6: 50000 | LM6: 0 | LN6: 0 | LO6: 50000 | LP6: 50000
IN7: INR | IO7: Input Tax SGST - GCF | IP7: Add | IQ7: 1250 | IR7: 1250 | IT7: Total | IU7: 0 | IV7: Main - GCF | IW7: Input Tax SGST @ 9.0 | IX7: sgst | IY7: 0 | IZ7: 0 | JA7: {"Freight Outward - GCF":[2.5,1250.0]} | JC7: 1250 | JD7: 1250 | JE7: 0 | JF7: 52500 | JG7: 52500 | JH7: On Net Total
IN8: INR | IO8: Input Tax CGST RCM - GCF | IP8: Deduct | IQ8: 1250 | IR8: 1250 | IT8: Total | IU8: 0 | IV8: Main - GCF | IW8: Input Tax CGST RCM @ 9.0 | IX8: cgst_rcm | IY8: 0 | IZ8: 0 | JA8: {"Freight Outward - GCF":[2.5,1250.0]} | JC8: 1250 | JD8: 1250 | JE8: 0 | JF8: 51250 | JG8: 51250 | JH8: On Net Total
IN9: INR | IO9: Input Tax SGST RCM - GCF | IP9: Deduct | IQ9: 1250 | IR9: 1250 | IT9: Total | IU9: 0 | IV9: Main - GCF | IW9: Input Tax SGST RCM @ 9.0 | IX9: sgst_rcm | IY9: 0 | IZ9: 0 | JA9: {"Freight Outward - GCF":[2.5,1250.0]} | JC9: 1250 | JD9: 1250 | JE9: 0 | JF9: 50000 | JG9: 50000 | JH9: On Net Total
A10: PI/G/25-26/0200 | B10: PI/G/25-26/0200-1 | C10: PINV-.YY.- | D10: Freight Outward Non TDS | E10: 45749 | F10: Ghaziabad | G10: Creditors - GCF | H10: Freight Outward Non TDS | I10: Freight Outward Non TDS | L10: G. C. Foods Pvt. Ltd. | M10: 0.61439815 | N10: 1 | O10: 45749 | Q10: 0 | R10: 0 | T10: 1 | U10: 0 | V10: 1 | W10: 0 | X10: 1 | AD10: INR | AE10: 1 | AF10: 1 | AG10: Standard Buying | AH10: INR | AI10: 1 | AJ10: 0 | AL10: 0 | AO10: 0 | AR10: 1 | AS10: 0 | AT10: 40000 | AU10: 40000 | AV10: 40000 | AW10: 40000 | AX10: 40000 | AY10: 40000 | BA10: Input GST RCM In-state - GCF | BE10: 2000 | BF10: 2000 | BG10: 0 | BH10: 2000 | BI10: 2000 | BJ10: 0 | BK10: 40000 | BL10: 0 | BM10: 0 | BN10: INR Forty Thousand only. | BO10: 40000 | BP10: 0 | BQ10: 0 | BR10: 0 | BS10: INR Forty Thousand only. | BT10: 0 | BU10: 40000 | BV10: 1 | BW10: Grand Total | BX10: 0 | BY10: 0 | BZ10: 0 | CA10: | HSN/SAC | Taxable Amount | Input Tax CGST @ 9.0 | Input Tax SGST @ 9.0 | Input Tax CGST RCM @ 9.0 | Input Tax SGST RCM @ 9.0 | | --- | --- | --- | --- | --- | --- | | 996511 | ₹ 40,000.00 | (2.5%) ₹ 1,000.00 | (2.5%) ₹ 1,000.00 | (2.5%) ₹ 1,000.00 | (2.5%) ₹ 1,000.00 | | CC10: 0 | CF10: 0 | CG10: 0 | CH10: 0 | CI10: 0 | CJ10: 0 | CP10: Unregistered | CW10: G.C. Foods Pvt. Ltd.Ghaziabad - Uttar Pradesh-Billing | CX10: C-4, Sector A-2, , Tronica city Indl. Area, LoniGhaziabad, Uttar Pradesh, State Code: 09, Pincode: 201103, India, Phone: 9350041990, GSTIN: 09AACCG2244H1ZS, | CY10: G.C. Foods Pvt. Ltd.Ghaziabad - Uttar Pradesh-Billing | CZ10: C-4, Sector A-2, , Tronica city Indl. Area, LoniGhaziabad, Uttar Pradesh, State Code: 09, Pincode: 201103, India, Phone: 9350041990, GSTIN: 09AACCG2244H1ZS, | DA10: 09AACCG2244H1ZS | DB10: 09-Uttar Pradesh | DD10: 0 | DG10: 0 | DH10: INR | DI10: No | DJ10: Freight Outward - GCF | DP10: GCF Letterhead | DQ10: 0 | DS10: en | DY10: 0 | EA10: Road | EC10: 45869 | ED10: Regular | EE10: ITC on Reverse Charge | EG10: Not Applicable | EH10: 0 | EK10: 0 | EM10: Creditors (Transport) | EO10: 0 | EP10: No Remarks | ER10: 1 | ES10: 1 | ET10: 40000 | EU10: 40000 | EV10: Freight Outward - GCF | EW10: 40000 | EX10: 40000 | EY10: Unit | EZ10: 1 | FB10: 0 | FC10: 1 | FI10: 0 | FJ10: 0 | FK10: 0 | FL10: 0 | FM10: 1000 | FN10: 2.5 | FO10: Main - GCF | FQ10: Freight Outward | FR10: 0 | FS10: 0 | FT10: 0 | FU10: 0 | FV10: Freight Outward - GCF | FX10: Taxable | FY10: 996511 | FZ10: 0 | GA10: 0 | GC10: 0 | GD10: 0 | GE10: 0 | GF10: 0 | GG10: Freight Outward - GCF | GH10: Services | GI10: 0 | GJ10: {"Output Tax SGST - GCF": 2.5, "Output Tax CGST - GCF": 2.5, "Output Tax IGST - GCF": 5.0, "Input Tax SGST - GCF": 2.5, "Input Tax CGST - GCF": 2.5, "Input Tax IGST - GCF": 5.0, "Input Tax SGST RCM - GCF": 2.5, "Input Tax CGST RCM - GCF": 2.5, "Input Tax IGST RCM - GCF": 5.0} | GK10: GST 5% - GCF | GL10: 0 | GO10: 0 | GS10: 40000 | GT10: 40000 | GU10: 40000 | GV10: 40000 | GW10: 0 | GX10: 1 | GY10: 0 | GZ10: 0 | HJ10: 40000 | HK10: 0 | HL10: 0 | HM10: 0 | HN10: 0 | HP10: 0 | HT10: 0 | IA10: 1000 | IB10: 2.5 | ID10: Unit | IE10: Ghaziabad | IF10: 40000 | IG10: 0 | IH10: 0 | II10: 0 | IJ10: 0 | IN10: INR | IO10: Input Tax CGST - GCF | IP10: Add | IQ10: 1000 | IR10: 1000 | IT10: Total | IU10: 0 | IV10: Main - GCF | IW10: Input Tax CGST @ 9.0 | IX10: cgst | IY10: 0 | IZ10: 0 | JA10: {"Freight Outward - GCF":[2.5,1000.0]} | JC10: 1000 | JD10: 1000 | JE10: 0 | JF10: 41000 | JG10: 41000 | JH10: On Net Total | LD10: 0 | LG10: 0 | LH10: 45749 | LI10: 100 | LK10: 40000 | LL10: 40000 | LM10: 0 | LN10: 0 | LO10: 40000 | LP10: 40000
IN11: INR | IO11: Input Tax SGST - GCF | IP11: Add | IQ11: 1000 | IR11: 1000 | IT11: Total | IU11: 0 | IV11: Main - GCF | IW11: Input Tax SGST @ 9.0 | IX11: sgst | IY11: 0 | IZ11: 0 | JA11: {"Freight Outward - GCF":[2.5,1000.0]} | JC11: 1000 | JD11: 1000 | JE11: 0 | JF11: 42000 | JG11: 42000 | JH11: On Net Total
IN12: INR | IO12: Input Tax CGST RCM - GCF | IP12: Deduct | IQ12: 1000 | IR12: 1000 | IT12: Total | IU12: 0 | IV12: Main - GCF | IW12: Input Tax CGST RCM @ 9.0 | IX12: cgst_rcm | IY12: 0 | IZ12: 0 | JA12: {"Freight Outward - GCF":[2.5,1000.0]} | JC12: 1000 | JD12: 1000 | JE12: 0 | JF12: 41000 | JG12: 41000 | JH12: On Net Total
IN13: INR | IO13: Input Tax SGST RCM - GCF | IP13: Deduct | IQ13: 1000 | IR13: 1000 | IT13: Total | IU13: 0 | IV13: Main - GCF | IW13: Input Tax SGST RCM @ 9.0 | IX13: sgst_rcm | IY13: 0 | IZ13: 0 | JA13: {"Freight Outward - GCF":[2.5,1000.0]} | JC13: 1000 | JD13: 1000 | JE13: 0 | JF13: 40000 | JG13: 40000 | JH13: On Net Total
A14: PI/M/25-26/0139 | B14: PI/M/25-26/0139-1 | C14: PINV-.YY.- | D14: Freight Outward Non TDS | E14: 45749 | F14: Muzaffarpur | G14: Creditors - GCF | H14: Freight Outward Non TDS | I14: Freight Outward Non TDS | L14: G. C. Foods Pvt. Ltd. | M14: 0.58376157 | N14: 1 | O14: 45749 | Q14: 0 | R14: 0 | T14: 1 | U14: 0 | V14: 1 | W14: 0 | X14: 1 | AD14: INR | AE14: 1 | AF14: 1 | AG14: Standard Buying | AH14: INR | AI14: 1 | AJ14: 0 | AL14: 0 | AO14: 0 | AR14: 1 | AS14: 0 | AT14: 2100 | AU14: 2100 | AV14: 2100 | AW14: 2100 | AX14: 2100 | AY14: 2100 | BA14: Input GST RCM In-state - GCF | BE14: 105 | BF14: 105 | BG14: 0 | BH14: 105 | BI14: 105 | BJ14: 0 | BK14: 2100 | BL14: 0 | BM14: 0 | BN14: INR Two Thousand, One Hundred only. | BO14: 2100 | BP14: 0 | BQ14: 0 | BR14: 0 | BS14: INR Two Thousand, One Hundred only. | BT14: 0 | BU14: 2100 | BV14: 1 | BW14: Grand Total | BX14: 0 | BY14: 0 | BZ14: 0 | CA14: | HSN/SAC | Taxable Amount | Input Tax CGST @ 9.0 | Input Tax SGST @ 9.0 | Input Tax CGST RCM @ 9.0 | Input Tax SGST RCM @ 9.0 | | --- | --- | --- | --- | --- | --- | | 996511 | ₹ 2,100.00 | (2.5%) ₹ 52.50 | (2.5%) ₹ 52.50 | (2.5%) ₹ 52.50 | (2.5%) ₹ 52.50 | | CC14: 0 | CF14: 0 | CG14: 0 | CH14: 0 | CI14: 0 | CJ14: 0 | CP14: Unregistered | CW14: GC Foods Muzaffarpur-Billing | CX14: A-03 and A-04, Bela Industrial Estate, Muzaffarpur, Bihar, State Code: 10, Pincode: 842005, India, GSTIN: 10AACCG2244H1Z9, | CY14: GC Foods Muzaffarpur-Billing | CZ14: A-03 and A-04, Bela Industrial Estate, Muzaffarpur, Bihar, State Code: 10, Pincode: 842005, India, GSTIN: 10AACCG2244H1Z9, | DA14: 10AACCG2244H1Z9 | DB14: 10-Bihar | DD14: 0 | DG14: 0 | DH14: INR | DI14: No | DJ14: Freight Outward - GCF | DP14: GCF Letterhead | DQ14: 0 | DS14: en | DY14: 0 | EA14: Road | EC14: 45869 | ED14: Regular | EE14: ITC on Reverse Charge | EG14: Not Applicable | EH14: 0 | EK14: 0 | EM14: Creditors (Transport) | EO14: 0 | EP14: No Remarks | ER14: 1 | ES14: 1 | ET14: 2100 | EU14: 2100 | EV14: Freight Outward - GCF | EW14: 2100 | EX14: 2100 | EY14: Unit | EZ14: 1 | FB14: 0 | FC14: 1 | FI14: 0 | FJ14: 0 | FK14: 0 | FL14: 0 | FM14: 52.5 | FN14: 2.5 | FO14: Main - GCF | FQ14: Freight Outward | FR14: 0 | FS14: 0 | FT14: 0 | FU14: 0 | FV14: Freight Outward - GCF | FX14: Taxable | FY14: 996511 | FZ14: 0 | GA14: 0 | GC14: 0 | GD14: 0 | GE14: 0 | GF14: 0 | GG14: Freight Outward - GCF | GH14: Services | GI14: 0 | GJ14: {"Output Tax SGST - GCF": 2.5, "Output Tax CGST - GCF": 2.5, "Output Tax IGST - GCF": 5.0, "Input Tax SGST - GCF": 2.5, "Input Tax CGST - GCF": 2.5, "Input Tax IGST - GCF": 5.0, "Input Tax SGST RCM - GCF": 2.5, "Input Tax CGST RCM - GCF": 2.5, "Input Tax IGST RCM - GCF": 5.0} | GK14: GST 5% - GCF | GL14: 0 | GO14: 0 | GS14: 2100 | GT14: 2100 | GU14: 2100 | GV14: 2100 | GW14: 0 | GX14: 1 | GY14: 0 | GZ14: 0 | HJ14: 2100 | HK14: 0 | HL14: 0 | HM14: 0 | HN14: 0 | HP14: 0 | HT14: 0 | IA14: 52.5 | IB14: 2.5 | ID14: Unit | IE14: Muzaffarpur | IF14: 2100 | IG14: 0 | IH14: 0 | II14: 0 | IJ14: 0 | IN14: INR | IO14: Input Tax CGST - GCF | IP14: Add | IQ14: 52.5 | IR14: 52.5 | IT14: Total | IU14: 0 | IV14: Main - GCF | IW14: Input Tax CGST @ 9.0 | IX14: cgst | IY14: 0 | IZ14: 0 | JA14: {"Freight Outward - GCF":[2.5,52.5]} | JC14: 52.5 | JD14: 52.5 | JE14: 0 | JF14: 2152.5 | JG14: 2152.5 | JH14: On Net Total | LD14: 0 | LG14: 0 | LH14: 45749 | LI14: 100 | LK14: 2100 | LL14: 2100 | LM14: 0 | LN14: 0 | LO14: 2100 | LP14: 2100
IN15: INR | IO15: Input Tax SGST - GCF | IP15: Add | IQ15: 52.5 | IR15: 52.5 | IT15: Total | IU15: 0 | IV15: Main - GCF | IW15: Input Tax SGST @ 9.0 | IX15: sgst | IY15: 0 | IZ15: 0 | JA15: {"Freight Outward - GCF":[2.5,52.5]} | JC15: 52.5 | JD15: 52.5 | JE15: 0 | JF15: 2205 | JG15: 2205 | JH15: On Net Total
IN16: INR | IO16: Input Tax CGST RCM - GCF | IP16: Deduct | IQ16: 52.5 | IR16: 52.5 | IT16: Total | IU16: 0 | IV16: Main - GCF | IW16: Input Tax CGST RCM @ 9.0 | IX16: cgst_rcm | IY16: 0 | IZ16: 0 | JA16: {"Freight Outward - GCF":[2.5,52.5]} | JC16: 52.5 | JD16: 52.5 | JE16: 0 | JF16: 2152.5 | JG16: 2152.5 | JH16: On Net Total
IN17: INR | IO17: Input Tax SGST RCM - GCF | IP17: Deduct | IQ17: 52.5 | IR17: 52.5 | IT17: Total | IU17: 0 | IV17: Main - GCF | IW17: Input Tax SGST RCM @ 9.0 | IX17: sgst_rcm | IY17: 0 | IZ17: 0 | JA17: {"Freight Outward - GCF":[2.5,52.5]} | JC17: 52.5 | JD17: 52.5 | JE17: 0 | JF17: 2100 | JG17: 2100 | JH17: On Net Total
A18: PI/M/25-26/0138 | B18: PI/M/25-26/0138-1 | C18: PINV-.YY.- | D18: Freight Outward Non TDS | E18: 45749 | F18: Muzaffarpur | G18: Creditors - GCF | H18: Freight Outward Non TDS | I18: Freight Outward Non TDS | L18: G. C. Foods Pvt. Ltd. | M18: 0.58346065 | N18: 1 | O18: 45749 | Q18: 0 | R18: 0 | T18: 1 | U18: 0 | V18: 1 | W18: 0 | X18: 1 | AD18: INR | AE18: 1 | AF18: 1 | AG18: Standard Buying | AH18: INR | AI18: 1 | AJ18: 0 | AL18: 0 | AO18: 0 | AR18: 1 | AS18: 0 | AT18: 1500 | AU18: 1500 | AV18: 1500 | AW18: 1500 | AX18: 1500 | AY18: 1500 | BA18: Input GST RCM In-state - GCF | BE18: 75 | BF18: 75 | BG18: 0 | BH18: 75 | BI18: 75 | BJ18: 0 | BK18: 1500 | BL18: 0 | BM18: 0 | BN18: INR One Thousand, Five Hundred only. | BO18: 1500 | BP18: 0 | BQ18: 0 | BR18: 0 | BS18: INR One Thousand, Five Hundred only. | BT18: 0 | BU18: 1500 | BV18: 1 | BW18: Grand Total | BX18: 0 | BY18: 0 | BZ18: 0 | CA18: | HSN/SAC | Taxable Amount | Input Tax CGST @ 9.0 | Input Tax SGST @ 9.0 | Input Tax CGST RCM @ 9.0 | Input Tax SGST RCM @ 9.0 | | --- | --- | --- | --- | --- | --- | | 996511 | ₹ 1,500.00 | (2.5%) ₹ 37.50 | (2.5%) ₹ 37.50 | (2.5%) ₹ 37.50 | (2.5%) ₹ 37.50 | | CC18: 0 | CF18: 0 | CG18: 0 | CH18: 0 | CI18: 0 | CJ18: 0 | CP18: Unregistered | CW18: GC Foods Muzaffarpur-Billing | CX18: A-03 and A-04, Bela Industrial Estate, Muzaffarpur, Bihar, State Code: 10, Pincode: 842005, India, GSTIN: 10AACCG2244H1Z9, | CY18: GC Foods Muzaffarpur-Billing | CZ18: A-03 and A-04, Bela Industrial Estate, Muzaffarpur, Bihar, State Code: 10, Pincode: 842005, India, GSTIN: 10AACCG2244H1Z9, | DA18: 10AACCG2244H1Z9 | DB18: 10-Bihar | DD18: 0 | DG18: 0 | DH18: INR | DI18: No | DJ18: Freight Outward - GCF | DP18: GCF Letterhead | DQ18: 0 | DS18: en | DY18: 0 | EA18: Road | EC18: 45869 | ED18: Regular | EE18: ITC on Reverse Charge | EG18: Not Applicable | EH18: 0 | EK18: 0 | EM18: Creditors (Transport) | EO18: 0 | EP18: No Remarks | ER18: 1 | ES18: 1 | ET18: 1500 | EU18: 1500 | EV18: Freight Outward - GCF | EW18: 1500 | EX18: 1500 | EY18: Unit | EZ18: 1 | FB18: 0 | FC18: 1 | FI18: 0 | FJ18: 0 | FK18: 0 | FL18: 0 | FM18: 37.5 | FN18: 2.5 | FO18: Main - GCF | FQ18: Freight Outward | FR18: 0 | FS18: 0 | FT18: 0 | FU18: 0 | FV18: Freight Outward - GCF | FX18: Taxable | FY18: 996511 | FZ18: 0 | GA18: 0 | GC18: 0 | GD18: 0 | GE18: 0 | GF18: 0 | GG18: Freight Outward - GCF | GH18: Services | GI18: 0 | GJ18: {"Output Tax SGST - GCF": 2.5, "Output Tax CGST - GCF": 2.5, "Output Tax IGST - GCF": 5.0, "Input Tax SGST - GCF": 2.5, "Input Tax CGST - GCF": 2.5, "Input Tax IGST - GCF": 5.0, "Input Tax SGST RCM - GCF": 2.5, "Input Tax CGST RCM - GCF": 2.5, "Input Tax IGST RCM - GCF": 5.0} | GK18: GST 5% - GCF | GL18: 0 | GO18: 0 | GS18: 1500 | GT18: 1500 | GU18: 1500 | GV18: 1500 | GW18: 0 | GX18: 1 | GY18: 0 | GZ18: 0 | HJ18: 1500 | HK18: 0 | HL18: 0 | HM18: 0 | HN18: 0 | HP18: 0 | HT18: 0 | IA18: 37.5 | IB18: 2.5 | ID18: Unit | IE18: Muzaffarpur | IF18: 1500 | IG18: 0 | IH18: 0 | II18: 0 | IJ18: 0 | IN18: INR | IO18: Input Tax CGST - GCF | IP18: Add | IQ18: 37.5 | IR18: 37.5 | IT18: Total | IU18: 0 | IV18: Main - GCF | IW18: Input Tax CGST @ 9.0 | IX18: cgst | IY18: 0 | IZ18: 0 | JA18: {"Freight Outward - GCF":[2.5,37.5]} | JC18: 37.5 | JD18: 37.5 | JE18: 0 | JF18: 1537.5 | JG18: 1537.5 | JH18: On Net Total | LD18: 0 | LG18: 0 | LH18: 45749 | LI18: 100 | LK18: 1500 | LL18: 1500 | LM18: 0 | LN18: 0 | LO18: 1500 | LP18: 1500
IN19: INR | IO19: Input Tax SGST - GCF | IP19: Add | IQ19: 37.5 | IR19: 37.5 | IT19: Total | IU19: 0 | IV19: Main - GCF | IW19: Input Tax SGST @ 9.0 | IX19: sgst | IY19: 0 | IZ19: 0 | JA19: {"Freight Outward - GCF":[2.5,37.5]} | JC19: 37.5 | JD19: 37.5 | JE19: 0 | JF19: 1575 | JG19: 1575 | JH19: On Net Total
IN20: INR | IO20: Input Tax CGST RCM - GCF | IP20: Deduct | IQ20: 37.5 | IR20: 37.5 | IT20: Total | IU20: 0 | IV20: Main - GCF | IW20: Input Tax CGST RCM @ 9.0 | IX20: cgst_rcm | IY20: 0 | IZ20: 0 | JA20: {"Freight Outward - GCF":[2.5,37.5]} | JC20: 37.5 | JD20: 37.5 | JE20: 0 | JF20: 1537.5 | JG20: 1537.5 | JH20: On Net Total
IN21: INR | IO21: Input Tax SGST RCM - GCF | IP21: Deduct | IQ21: 37.5 | IR21: 37.5 | IT21: Total | IU21: 0 | IV21: Main - GCF | IW21: Input Tax SGST RCM @ 9.0 | IX21: sgst_rcm | IY21: 0 | IZ21: 0 | JA21: {"Freight Outward - GCF":[2.5,37.5]} | JC21: 37.5 | JD21: 37.5 | JE21: 0 | JF21: 1500 | JG21: 1500 | JH21: On Net Total
A22: PI/M/25-26/0137 | B22: PI/M/25-26/0137-1 | C22: PINV-.YY.- | D22: Freight Outward Non TDS | E22: 45749 | F22: Muzaffarpur | G22: Creditors - GCF | H22: Freight Outward Non TDS | I22: Freight Outward Non TDS | L22: G. C. Foods Pvt. Ltd. | M22: 0.5794213 | N22: 1 | O22: 45749 | Q22: 0 | R22: 0 | T22: 1 | U22: 0 | V22: 1 | W22: 0 | X22: 1 | AD22: INR | AE22: 1 | AF22: 1 | AG22: Standard Buying | AH22: INR | AI22: 1 | AJ22: 0 | AL22: 0 | AO22: 0 | AR22: 1 | AS22: 0 | AT22: 600 | AU22: 600 | AV22: 600 | AW22: 600 | AX22: 600 | AY22: 600 | BA22: Input GST RCM In-state - GCF | BE22: 30 | BF22: 30 | BG22: 0 | BH22: 30 | BI22: 30 | BJ22: 0 | BK22: 600 | BL22: 0 | BM22: 0 | BN22: INR Six Hundred only. | BO22: 600 | BP22: 0 | BQ22: 0 | BR22: 0 | BS22: INR Six Hundred only. | BT22: 0 | BU22: 600 | BV22: 1 | BW22: Grand Total | BX22: 0 | BY22: 0 | BZ22: 0 | CA22: | HSN/SAC | Taxable Amount | Input Tax CGST @ 9.0 | Input Tax SGST @ 9.0 | Input Tax CGST RCM @ 9.0 | Input Tax SGST RCM @ 9.0 | | --- | --- | --- | --- | --- | --- | | 996511 | ₹ 600.00 | (2.5%) ₹ 15.00 | (2.5%) ₹ 15.00 | (2.5%) ₹ 15.00 | (2.5%) ₹ 15.00 | | CC22: 0 | CF22: 0 | CG22: 0 | CH22: 0 | CI22: 0 | CJ22: 0 | CP22: Unregistered | CW22: GC Foods Muzaffarpur-Billing | CX22: A-03 and A-04, Bela Industrial Estate, Muzaffarpur, Bihar, State Code: 10, Pincode: 842005, India, GSTIN: 10AACCG2244H1Z9, | CY22: GC Foods Muzaffarpur-Billing | CZ22: A-03 and A-04, Bela Industrial Estate, Muzaffarpur, Bihar, State Code: 10, Pincode: 842005, India, GSTIN: 10AACCG2244H1Z9, | DA22: 10AACCG2244H1Z9 | DB22: 10-Bihar | DD22: 0 | DG22: 0 | DH22: INR | DI22: No | DJ22: Freight Outward - GCF | DP22: GCF Letterhead | DQ22: 0 | DS22: en | DY22: 0 | EA22: Road | EC22: 45869 | ED22: Regular | EE22: ITC on Reverse Charge | EG22: Not Applicable | EH22: 0 | EK22: 0 | EM22: Creditors (Transport) | EO22: 0 | EP22: No Remarks | ER22: 1 | ES22: 1 | ET22: 600 | EU22: 600 | EV22: Freight Outward - GCF | EW22: 600 | EX22: 600 | EY22: Unit | EZ22: 1 | FB22: 0 | FC22: 1 | FI22: 0 | FJ22: 0 | FK22: 0 | FL22: 0 | FM22: 15 | FN22: 2.5 | FO22: Main - GCF | FQ22: Freight Outward | FR22: 0 | FS22: 0 | FT22: 0 | FU22: 0 | FV22: Freight Outward - GCF | FX22: Taxable | FY22: 996511 | FZ22: 0 | GA22: 0 | GC22: 0 | GD22: 0 | GE22: 0 | GF22: 0 | GG22: Freight Outward - GCF | GH22: Services | GI22: 0 | GJ22: {"Output Tax SGST - GCF": 2.5, "Output Tax CGST - GCF": 2.5, "Output Tax IGST - GCF": 5.0, "Input Tax SGST - GCF": 2.5, "Input Tax CGST - GCF": 2.5, "Input Tax IGST - GCF": 5.0, "Input Tax SGST RCM - GCF": 2.5, "Input Tax CGST RCM - GCF": 2.5, "Input Tax IGST RCM - GCF": 5.0} | GK22: GST 5% - GCF | GL22: 0 | GO22: 0 | GS22: 600 | GT22: 600 | GU22: 600 | GV22: 600 | GW22: 0 | GX22: 1 | GY22: 0 | GZ22: 0 | HJ22: 600 | HK22: 0 | HL22: 0 | HM22: 0 | HN22: 0 | HP22: 0 | HT22: 0 | IA22: 15 | IB22: 2.5 | ID22: Unit | IE22: Muzaffarpur | IF22: 600 | IG22: 0 | IH22: 0 | II22: 0 | IJ22: 0 | IN22: INR | IO22: Input Tax CGST - GCF | IP22: Add | IQ22: 15 | IR22: 15 | IT22: Total | IU22: 0 | IV22: Main - GCF | IW22: Input Tax CGST @ 9.0 | IX22: cgst | IY22: 0 | IZ22: 0 | JA22: {"Freight Outward - GCF":[2.5,15.0]} | JC22: 15 | JD22: 15 | JE22: 0 | JF22: 615 | JG22: 615 | JH22: On Net Total | LD22: 0 | LG22: 0 | LH22: 45749 | LI22: 100 | LK22: 600 | LL22: 600 | LM22: 0 | LN22: 0 | LO22: 600 | LP22: 600
IN23: INR | IO23: Input Tax SGST - GCF | IP23: Add | IQ23: 15 | IR23: 15 | IT23: Total | IU23: 0 | IV23: Main - GCF | IW23: Input Tax SGST @ 9.0 | IX23: sgst | IY23: 0 | IZ23: 0 | JA23: {"Freight Outward - GCF":[2.5,15.0]} | JC23: 15 | JD23: 15 | JE23: 0 | JF23: 630 | JG23: 630 | JH23: On Net Total
IN24: INR | IO24: Input Tax CGST RCM - GCF | IP24: Deduct | IQ24: 15 | IR24: 15 | IT24: Total | IU24: 0 | IV24: Main - GCF | IW24: Input Tax CGST RCM @ 9.0 | IX24: cgst_rcm | IY24: 0 | IZ24: 0 | JA24: {"Freight Outward - GCF":[2.5,15.0]} | JC24: 15 | JD24: 15 | JE24: 0 | JF24: 615 | JG24: 615 | JH24: On Net Total
IN25: INR | IO25: Input Tax SGST RCM - GCF | IP25: Deduct | IQ25: 15 | IR25: 15 | IT25: Total | IU25: 0 | IV25: Main - GCF | IW25: Input Tax SGST RCM @ 9.0 | IX25: sgst_rcm | IY25: 0 | IZ25: 0 | JA25: {"Freight Outward - GCF":[2.5,15.0]} | JC25: 15 | JD25: 15 | JE25: 0 | JF25: 600 | JG25: 600 | JH25: On Net Total
A26: PI/M/25-26/0136 | B26: PI/M/25-26/0136-1 | C26: PINV-.YY.- | D26: Freight Outward Non TDS | E26: 45749 | F26: Muzaffarpur | G26: Creditors - GCF | H26: Freight Outward Non TDS | I26: Freight Outward Non TDS | L26: G. C. Foods Pvt. Ltd. | M26: 0.57923611 | N26: 1 | O26: 45749 | Q26: 0 | R26: 0 | T26: 1 | U26: 0 | V26: 1 | W26: 0 | X26: 1 | AD26: INR | AE26: 1 | AF26: 1 | AG26: Standard Buying | AH26: INR | AI26: 1 | AJ26: 0 | AL26: 0 | AO26: 0 | AR26: 1 | AS26: 0 | AT26: 600 | AU26: 600 | AV26: 600 | AW26: 600 | AX26: 600 | AY26: 600 | BA26: Input GST RCM In-state - GCF | BE26: 30 | BF26: 30 | BG26: 0 | BH26: 30 | BI26: 30 | BJ26: 0 | BK26: 600 | BL26: 0 | BM26: 0 | BN26: INR Six Hundred only. | BO26: 600 | BP26: 0 | BQ26: 0 | BR26: 0 | BS26: INR Six Hundred only. | BT26: 0 | BU26: 600 | BV26: 1 | BW26: Grand Total | BX26: 0 | BY26: 0 | BZ26: 0 | CA26: | HSN/SAC | Taxable Amount | Input Tax CGST @ 9.0 | Input Tax SGST @ 9.0 | Input Tax CGST RCM @ 9.0 | Input Tax SGST RCM @ 9.0 | | --- | --- | --- | --- | --- | --- | | 996511 | ₹ 600.00 | (2.5%) ₹ 15.00 | (2.5%) ₹ 15.00 | (2.5%) ₹ 15.00 | (2.5%) ₹ 15.00 | | CC26: 0 | CF26: 0 | CG26: 0 | CH26: 0 | CI26: 0 | CJ26: 0 | CP26: Unregistered | CW26: GC Foods Muzaffarpur-Billing | CX26: A-03 and A-04, Bela Industrial Estate, Muzaffarpur, Bihar, State Code: 10, Pincode: 842005, India, GSTIN: 10AACCG2244H1Z9, | CY26: GC Foods Muzaffarpur-Billing | CZ26: A-03 and A-04, Bela Industrial Estate, Muzaffarpur, Bihar, State Code: 10, Pincode: 842005, India, GSTIN: 10AACCG2244H1Z9, | DA26: 10AACCG2244H1Z9 | DB26: 10-Bihar | DD26: 0 | DG26: 0 | DH26: INR | DI26: No | DJ26: Freight Outward - GCF | DP26: GCF Letterhead | DQ26: 0 | DS26: en | DY26: 0 | EA26: Road | EC26: 45869 | ED26: Regular | EE26: ITC on Reverse Charge | EG26: Not Applicable | EH26: 0 | EK26: 0 | EM26: Creditors (Transport) | EO26: 0 | EP26: No Remarks | ER26: 1 | ES26: 1 | ET26: 600 | EU26: 600 | EV26: Freight Outward - GCF | EW26: 600 | EX26: 600 | EY26: Unit | EZ26: 1 | FB26: 0 | FC26: 1 | FI26: 0 | FJ26: 0 | FK26: 0 | FL26: 0 | FM26: 15 | FN26: 2.5 | FO26: Main - GCF | FQ26: Freight Outward | FR26: 0 | FS26: 0 | FT26: 0 | FU26: 0 | FV26: Freight Outward - GCF | FX26: Taxable | FY26: 996511 | FZ26: 0 | GA26: 0 | GC26: 0 | GD26: 0 | GE26: 0 | GF26: 0 | GG26: Freight Outward - GCF | GH26: Services | GI26: 0 | GJ26: {"Output Tax SGST - GCF": 2.5, "Output Tax CGST - GCF": 2.5, "Output Tax IGST - GCF": 5.0, "Input Tax SGST - GCF": 2.5, "Input Tax CGST - GCF": 2.5, "Input Tax IGST - GCF": 5.0, "Input Tax SGST RCM - GCF": 2.5, "Input Tax CGST RCM - GCF": 2.5, "Input Tax IGST RCM - GCF": 5.0} | GK26: GST 5% - GCF | GL26: 0 | GO26: 0 | GS26: 600 | GT26: 600 | GU26: 600 | GV26: 600 | GW26: 0 | GX26: 1 | GY26: 0 | GZ26: 0 | HJ26: 600 | HK26: 0 | HL26: 0 | HM26: 0 | HN26: 0 | HP26: 0 | HT26: 0 | IA26: 15 | IB26: 2.5 | ID26: Unit | IE26: Muzaffarpur | IF26: 600 | IG26: 0 | IH26: 0 | II26: 0 | IJ26: 0 | IN26: INR | IO26: Input Tax CGST - GCF | IP26: Add | IQ26: 15 | IR26: 15 | IT26: Total | IU26: 0 | IV26: Main - GCF | IW26: Input Tax CGST @ 9.0 | IX26: cgst | IY26: 0 | IZ26: 0 | JA26: {"Freight Outward - GCF":[2.5,15.0]} | JC26: 15 | JD26: 15 | JE26: 0 | JF26: 615 | JG26: 615 | JH26: On Net Total | LD26: 0 | LG26: 0 | LH26: 45749 | LI26: 100 | LK26: 600 | LL26: 600 | LM26: 0 | LN26: 0 | LO26: 600 | LP26: 600
IN27: INR | IO27: Input Tax SGST - GCF | IP27: Add | IQ27: 15 | IR27: 15 | IT27: Total | IU27: 0 | IV27: Main - GCF | IW27: Input Tax SGST @ 9.0 | IX27: sgst | IY27: 0 | IZ27: 0 | JA27: {"Freight Outward - GCF":[2.5,15.0]} | JC27: 15 | JD27: 15 | JE27: 0 | JF27: 630 | JG27: 630 | JH27: On Net Total
IN28: INR | IO28: Input Tax CGST RCM - GCF | IP28: Deduct | IQ28: 15 | IR28: 15 | IT28: Total | IU28: 0 | IV28: Main - GCF | IW28: Input Tax CGST RCM @ 9.0 | IX28: cgst_rcm | IY28: 0 | IZ28: 0 | JA28: {"Freight Outward - GCF":[2.5,15.0]} | JC28: 15 | JD28: 15 | JE28: 0 | JF28: 615 | JG28: 615 | JH28: On Net Total
IN29: INR | IO29: Input Tax SGST RCM - GCF | IP29: Deduct | IQ29: 15 | IR29: 15 | IT29: Total | IU29: 0 | IV29: Main - GCF | IW29: Input Tax SGST RCM @ 9.0 | IX29: sgst_rcm | IY29: 0 | IZ29: 0 | JA29: {"Freight Outward - GCF":[2.5,15.0]} | JC29: 15 | JD29: 15 | JE29: 0 | JF29: 600 | JG29: 600 | JH29: On Net Total
A30: PI/M/25-26/0135 | B30: PI/M/25-26/0135-1 | C30: PINV-.YY.- | D30: Freight Outward Non TDS | E30: 45749 | F30: Muzaffarpur | G30: Creditors - GCF | H30: Freight Outward Non TDS | I30: Freight Outward Non TDS | L30: G. C. Foods Pvt. Ltd. | M30: 0.5730787 | N30: 1 | O30: 45749 | Q30: 0 | R30: 0 | T30: 1 | U30: 0 | V30: 1 | W30: 0 | X30: 1 | AD30: INR | AE30: 1 | AF30: 1 | AG30: Standard Buying | AH30: INR | AI30: 1 | AJ30: 0 | AL30: 0 | AO30: 0 | AR30: 1 | AS30: 0 | AT30: 600 | AU30: 600 | AV30: 600 | AW30: 600 | AX30: 600 | AY30: 600 | BA30: Input GST RCM In-state - GCF | BE30: 30 | BF30: 30 | BG30: 0 | BH30: 30 | BI30: 30 | BJ30: 0 | BK30: 600 | BL30: 0 | BM30: 0 | BN30: INR Six Hundred only. | BO30: 600 | BP30: 0 | BQ30: 0 | BR30: 0 | BS30: INR Six Hundred only. | BT30: 0 | BU30: 600 | BV30: 1 | BW30: Grand Total | BX30: 0 | BY30: 0 | BZ30: 0 | CA30: | HSN/SAC | Taxable Amount | Input Tax CGST @ 9.0 | Input Tax SGST @ 9.0 | Input Tax CGST RCM @ 9.0 | Input Tax SGST RCM @ 9.0 | | --- | --- | --- | --- | --- | --- | | 996511 | ₹ 600.00 | (2.5%) ₹ 15.00 | (2.5%) ₹ 15.00 | (2.5%) ₹ 15.00 | (2.5%) ₹ 15.00 | | CC30: 0 | CF30: 0 | CG30: 0 | CH30: 0 | CI30: 0 | CJ30: 0 | CP30: Unregistered | CW30: GC Foods Muzaffarpur-Billing | CX30: A-03 and A-04, Bela Industrial Estate, Muzaffarpur, Bihar, State Code: 10, Pincode: 842005, India, GSTIN: 10AACCG2244H1Z9, | CY30: GC Foods Muzaffarpur-Billing | CZ30: A-03 and A-04, Bela Industrial Estate, Muzaffarpur, Bihar, State Code: 10, Pincode: 842005, India, GSTIN: 10AACCG2244H1Z9, | DA30: 10AACCG2244H1Z9 | DB30: 10-Bihar | DD30: 0 | DG30: 0 | DH30: INR | DI30: No | DJ30: Freight Outward - GCF | DP30: GCF Letterhead | DQ30: 0 | DS30: en | DY30: 0 | EA30: Road | EC30: 45869 | ED30: Regular | EE30: ITC on Reverse Charge | EG30: Not Applicable | EH30: 0 | EK30: 0 | EM30: Creditors (Transport) | EO30: 0 | EP30: No Remarks | ER30: 1 | ES30: 1 | ET30: 600 | EU30: 600 | EV30: Freight Outward - GCF | EW30: 600 | EX30: 600 | EY30: Unit | EZ30: 1 | FB30: 0 | FC30: 1 | FI30: 0 | FJ30: 0 | FK30: 0 | FL30: 0 | FM30: 15 | FN30: 2.5 | FO30: Main - GCF | FQ30: Freight Outward | FR30: 0 | FS30: 0 | FT30: 0 | FU30: 0 | FV30: Freight Outward - GCF | FX30: Taxable | FY30: 996511 | FZ30: 0 | GA30: 0 | GC30: 0 | GD30: 0 | GE30: 0 | GF30: 0 | GG30: Freight Outward - GCF | GH30: Services | GI30: 0 | GJ30: {"Output Tax SGST - GCF": 2.5, "Output Tax CGST - GCF": 2.5, "Output Tax IGST - GCF": 5.0, "Input Tax SGST - GCF": 2.5, "Input Tax CGST - GCF": 2.5, "Input Tax IGST - GCF": 5.0, "Input Tax SGST RCM - GCF": 2.5, "Input Tax CGST RCM - GCF": 2.5, "Input Tax IGST RCM - GCF": 5.0} | GK30: GST 5% - GCF | GL30: 0 | GO30: 0 | GS30: 600 | GT30: 600 | GU30: 600 | GV30: 600 | GW30: 0 | GX30: 1 | GY30: 0 | GZ30: 0 | HJ30: 600 | HK30: 0 | HL30: 0 | HM30: 0 | HN30: 0 | HP30: 0 | HT30: 0 | IA30: 15 | IB30: 2.5 | ID30: Unit | IE30: Muzaffarpur | IF30: 600 | IG30: 0 | IH30: 0 | II30: 0 | IJ30: 0 | IN30: INR | IO30: Input Tax CGST - GCF | IP30: Add | IQ30: 15 | IR30: 15 | IT30: Total | IU30: 0 | IV30: Main - GCF | IW30: Input Tax CGST @ 9.0 | IX30: cgst | IY30: 0 | IZ30: 0 | JA30: {"Freight Outward - GCF":[2.5,15.0]} | JC30: 15 | JD30: 15 | JE30: 0 | JF30: 615 | JG30: 615 | JH30: On Net Total | LD30: 0 | LG30: 0 | LH30: 45749 | LI30: 100 | LK30: 600 | LL30: 600 | LM30: 0 | LN30: 0 | LO30: 600 | LP30: 600
IN31: INR | IO31: Input Tax SGST - GCF | IP31: Add | IQ31: 15 | IR31: 15 | IT31: Total | IU31: 0 | IV31: Main - GCF | IW31: Input Tax SGST @ 9.0 | IX31: sgst | IY31: 0 | IZ31: 0 | JA31: {"Freight Outward - GCF":[2.5,15.0]} | JC31: 15 | JD31: 15 | JE31: 0 | JF31: 630 | JG31: 630 | JH31: On Net Total
IN32: INR | IO32: Input Tax CGST RCM - GCF | IP32: Deduct | IQ32: 15 | IR32: 15 | IT32: Total | IU32: 0 | IV32: Main - GCF | IW32: Input Tax CGST RCM @ 9.0 | IX32: cgst_rcm | IY32: 0 | IZ32: 0 | JA32: {"Freight Outward - GCF":[2.5,15.0]} | JC32: 15 | JD32: 15 | JE32: 0 | JF32: 615 | JG32: 615 | JH32: On Net Total
IN33: INR | IO33: Input Tax SGST RCM - GCF | IP33: Deduct | IQ33: 15 | IR33: 15 | IT33: Total | IU33: 0 | IV33: Main - GCF | IW33: Input Tax SGST RCM @ 9.0 | IX33: sgst_rcm | IY33: 0 | IZ33: 0 | JA33: {"Freight Outward - GCF":[2.5,15.0]} | JC33: 15 | JD33: 15 | JE33: 0 | JF33: 600 | JG33: 600 | JH33: On Net Total
A34: PI/M/25-26/0132 | B34: PI/M/25-26/0132-1 | C34: PINV-.YY.- | D34: Jogi Jee Patna | E34: 45866 | F34: Muzaffarpur | G34: Creditors - GCF | H34: Jogi Jee Patna | I34: Jogi Jee Patna | L34: G. C. Foods Pvt. Ltd. | M34: 0.61065559 | N34: 1 | O34: 45866 | Q34: 0 | R34: 0 | T34: 1 | U34: 0 | V34: 1 | W34: 0 | X34: 0 | AA34: 45866 | AD34: INR | AE34: 1 | AF34: 1 | AG34: Standard Buying | AH34: INR | AI34: 1 | AJ34: 0 | AL34: 0 | AM34: Store Mujaffarpur - GCF | AO34: 0 | AR34: 4740 | AS34: 0 | AT34: 26544 | AU34: 26544 | AV34: 26544 | AW34: 26544 | AX34: 26544 | AY34: 26544 | BE34: 6 | BF34: 0 | BG34: 6 | BH34: 6 | BI34: 0 | BJ34: 6 | BK34: 26550 | BL34: 0 | BM34: 0 | BN34: INR Twenty Six Thousand, Five Hundred And Fifty only. | BO34: 26550 | BP34: 0 | BQ34: 0 | BR34: 0 | BS34: INR Twenty Six Thousand, Five Hundred And Fifty only. | BT34: 0 | BU34: 26550 | BV34: 1 | BW34: Grand Total | BX34: 0 | BY34: 0 | BZ34: 0 | CA34: | HSN/SAC | Taxable Amount | Rounded Off | | --- | --- | --- | | 08055000 | ₹ 26,544.00 | ₹ 6.00 | | CC34: 0 | CF34: 0 | CG34: 0 | CH34: 0 | CI34: 0 | CJ34: 0 | CP34: Unregistered | CW34: GC Foods Muzaffarpur-Billing | CX34: A-03 and A-04, Bela Industrial Estate, Muzaffarpur, Bihar, State Code: 10, Pincode: 842005, India, GSTIN: 10AACCG2244H1Z9, | CY34: GC Foods Muzaffarpur-Billing | CZ34: A-03 and A-04, Bela Industrial Estate, Muzaffarpur, Bihar, State Code: 10, Pincode: 842005, India, GSTIN: 10AACCG2244H1Z9, | DA34: 10AACCG2244H1Z9 | DB34: 10-Bihar | DD34: 0 | DF34: Lemon 4740 Kg (118 Bag ) as per Ingate Voucher No.1133 | DG34: 100 | DH34: INR | DI34: No | DJ34: Stock Received But Not Billed - GCF | DP34: GCF Letterhead | DQ34: 0 | DS34: en | DY34: 0 | EA34: Road | EC34: 45867 | ED34: Regular | EE34: All Other ITC | EG34: Not Applicable | EH34: 0 | EK34: 0 | EO34: 0 | EP34: No Remarks | ER34: 4740 | ES34: 4740 | ET34: 26544 | EU34: 26544 | EV34: Lemon | EW34: 5.6 | EX34: 5.6 | EY34: KGS | EZ34: 1 | FA34: Store Mujaffarpur - GCF | FB34: 0 | FC34: 1 | FI34: 0 | FJ34: 0 | FK34: 0 | FL34: 0 | FM34: 0 | FN34: 0 | FO34: Main - GCF | FQ34: Lemon | FR34: 14.4 | FS34: 72 | FT34: 0 | FU34: 0 | FV34: Stock Received But Not Billed - GCF | FX34: Nil-Rated | FY34: 08055000 | FZ34: 0 | GA34: 0 | GC34: 0 | GD34: 0 | GE34: 0 | GF34: 0 | GG34: Lemon | GH34: Spices and Seasoning - RM | GI34: 0 | GJ34: {} | GL34: 0 | GO34: 0 | GS34: 26544 | GT34: 26544 | GU34: 5.6 | GV34: 5.6 | GW34: 0 | GX34: 4740 | GY34: 20 | GZ34: 20 | HG34: PR/M/25-26/0128 | HH34: 779ntpsl6o | HJ34: 5.6 | HK34: 0 | HL34: 0 | HM34: 0 | HN34: 4740 | HP34: 0 | HT34: 0 | IA34: 0 | IB34: 0 | ID34: KGS | IE34: Muzaffarpur | IF34: 26550 | IG34: 0 | IH34: 0 | II34: 5.6 | IJ34: 0 | IN34: INR | IO34: Rounded Off - GCF | IP34: Add | IQ34: 6 | IR34: 6 | IT34: Total | IU34: 0 | IV34: Main - GCF | IW34: Rounded Off | IY34: 0 | IZ34: 0 | JA34: {"Lemon":[0.0,6.0]} | JC34: 6 | JD34: 6 | JE34: 0 | JF34: 26550 | JG34: 26550 | JH34: Actual | LD34: 0 | LF34: Percentage | LG34: 0 | LH34: 45866 | LI34: 100 | LK34: 26550 | LL34: 26550 | LM34: 0 | LN34: 0 | LO34: 26550 | LP34: 26550
A35: PI/N/25-26/0042 | B35: PI/N/25-26/0042-1 | C35: PINV-.YY.- | D35: Bajrang Traders | E35: 45860 | F35: Noida | G35: Creditors - GCF | H35: Bajrang Traders | I35: Bajrang Traders | L35: G. C. Foods Pvt. Ltd. | M35: 0.6595488 | N35: 1 | O35: 45860 | Q35: 0 | R35: 0 | T35: 1 | U35: 0 | V35: 1 | W35: 0 | X35: 0 | Z35: TAX/25-26/75 | AA35: 45860 | AD35: INR | AE35: 1 | AF35: 1 | AG35: Standard Buying | AH35: INR | AI35: 1 | AJ35: 0 | AL35: 0 | AM35: Stores Noida - GCF | AO35: 0 | AR35: 26 | AS35: 0 | AT35: 38060 | AU35: 38060 | AV35: 38060 | AW35: 38060 | AX35: 38060 | AY35: 38060 | BA35: Input GST In-state - GCF | BE35: 0 | BF35: 0 | BG35: 0 | BH35: 0 | BI35: 0 | BJ35: 0 | BK35: 38060 | BL35: 0 | BM35: 0 | BN35: INR Thirty Eight Thousand And Sixty only. | BO35: 38060 | BP35: 0 | BQ35: 0 | BR35: 0 | BS35: INR Thirty Eight Thousand And Sixty only. | BT35: 0 | BU35: 38060 | BV35: 1 | BW35: Grand Total | BX35: 0 | BY35: 0 | BZ35: 0 | CA35: | HSN/SAC | Taxable Amount | Input Tax CGST @ 9.0 | Input Tax SGST @ 9.0 | | --- | --- | --- | --- | | 11010000 | ₹ 36,610.00 | (0.0%) ₹ 0.00 | (0.0%) ₹ 0.00 | | 110100 | ₹ 1,450.00 | (0.0%) ₹ 0.00 | (0.0%) ₹ 0.00 | | CC35: 0 | CF35: 0 | CG35: 0 | CH35: 0 | CI35: 0 | CJ35: 0 | CM35: Bajrang Traders-Billing | CN35: Ghaza Road, BangelNoida, Uttar Pradesh, State Code: 09, Pincode: 201304, India, GSTIN: 09BGHPB1865L1Z6, | CO35: 09BGHPB1865L1Z6 | CP35: Registered Regular | CU35: Bajrang Traders-Billing | CV35: Ghaza Road, BangelNoida, Uttar Pradesh, State Code: 09, Pincode: 201304, India, GSTIN: 09BGHPB1865L1Z6, | CW35: G.C. Foods Pvt. Ltd. Noida - Uttar Pradesh (Shipping) | CX35: B-64, Sector-80,, Noida, Gautam Buddha Nagar, Noida, Uttar Pradesh, State Code: 09, Pincode: 201305, India, Phone: 9958003759, GSTIN: 09AACCG2244H1ZS, | CY35: G.C. Foods Pvt. Ltd. Noida - Uttar Pradesh (Shipping) | CZ35: B-64, Sector-80,, Noida, Gautam Buddha Nagar, Noida, Uttar Pradesh, State Code: 09, Pincode: 201305, India, Phone: 9958003759, GSTIN: 09AACCG2244H1ZS, | DA35: 09AACCG2244H1ZS | DB35: 09-Uttar Pradesh | DD35: 0 | DF35: Ingate No.166 , Date - 22.07.2025 | DG35: 100 | DH35: INR | DI35: No | DJ35: Stock Received But Not Billed - GCF | DP35: GCF Letterhead | DQ35: 0 | DS35: en | DY35: 0 | EA35: Road | EC35: 45864 | ED35: Regular | EE35: All Other ITC | EG35: Unreconciled | EH35: 0 | EK35: 0 | EM35: Creditors - Raw Material | EO35: 0 | EP35: Against Supplier Invoice TAX/25-26/75 dated 22-07-2025 | ER35: 18 | ES35: 792 | ET35: 25200 | EU35: 25200 | EV35: Maida Normal | EW35: 1400 | EX35: 1400 | EY35: BAG | EZ35: 44 | FA35: Stores Noida - GCF | FB35: 0 | FC35: 1 | FI35: 0 | FJ35: 0 | FK35: 0 | FL35: 0 | FM35: 0 | FN35: 0 | FO35: Main - GCF | FQ35: Maida | FR35: -70 | FS35: 0 | FT35: 0 | FU35: 0 | FV35: Stock Received But Not Billed - GCF | FX35: Exempted | FY35: 11010000 | FZ35: 0 | GA35: 0 | GC35: 0 | GD35: 0 | GE35: 0 | GF35: 0 | GG35: Maida | GH35: Cookies - RM | GI35: 0 | GJ35: {"Input Tax CGST - GCF": 0.0, "Input Tax SGST - GCF": 0.0, "Input Tax IGST - GCF": 0.0, "Output Tax CGST - GCF": 0.0, "Output Tax SGST - GCF": 0.0, "Output Tax IGST - GCF": 0.0, "Input Tax CGST RCM - GCF": 0.0, "Input Tax SGST RCM - GCF": 0.0, "Input Tax IGST RCM - GCF": 0.0} | GK35: Exempted - GCF | GL35: 0 | GO35: 70 | GP35: Amount | GS35: 25200 | GT35: 25200 | GU35: 1400 | GV35: 1400 | GW35: 0 | GX35: 18 | GY35: 1330 | GZ35: 1330 | HE35: PO/N/25-26/0032 | HF35: 4c44spgpm0 | HG35: PR/N/25-26/0082 | HH35: 9cr4p32clf | HJ35: 31.82 | HK35: 0 | HL35: 0 | HM35: 0 | HN35: 18 | HP35: 0 | HT35: 0 | IA35: 0 | IB35: 0 | ID35: KGS | IE35: Noida | IF35: 25200 | IG35: 0 | IH35: 0 | II35: 31.818182 | IJ35: 0 | IN35: INR | IO35: Input Tax CGST - GCF | IP35: Add | IQ35: 0 | IR35: 0 | IT35: Total | IU35: 0 | IV35: Main - GCF | IW35: Input Tax CGST @ 9.0 | IX35: cgst | IY35: 0 | IZ35: 0 | JA35: {"Maida":[0.0,0.0],"Maida Patent":[0.0,0.0],"Suji":[0.0,0.0]} | JC35: 0 | JD35: 0 | JE35: 0 | JF35: 38060 | JG35: 38060 | JH35: On Net Total | LD35: 0 | LF35: Percentage | LG35: 0 | LH35: 45860 | LI35: 100 | LK35: 38060 | LL35: 38060 | LM35: 0 | LN35: 0 | LO35: 38060 | LP35: 38060
ER36: 7 | ES36: 350 | ET36: 11410 | EU36: 11410 | EV36: Maida Patent | EW36: 1630 | EX36: 1630 | EY36: BAG | EZ36: 50 | FA36: Stores Noida - GCF | FB36: 0 | FC36: 1 | FI36: 0 | FJ36: 0 | FK36: 0 | FL36: 0 | FM36: 0 | FN36: 0 | FO36: Main - GCF | FQ36: Maida Rusk | FR36: -80 | FS36: 0 | FT36: 0 | FU36: 0 | FV36: Stock Received But Not Billed - GCF | FX36: Exempted | FY36: 11010000 | FZ36: 0 | GA36: 0 | GC36: 0 | GD36: 0 | GE36: 0 | GF36: 0 | GG36: Maida Patent | GH36: Cookies - RM | GI36: 0 | GJ36: {"Input Tax CGST - GCF": 0.0, "Input Tax SGST - GCF": 0.0, "Input Tax IGST - GCF": 0.0, "Output Tax CGST - GCF": 0.0, "Output Tax SGST - GCF": 0.0, "Output Tax IGST - GCF": 0.0, "Input Tax CGST RCM - GCF": 0.0, "Input Tax SGST RCM - GCF": 0.0, "Input Tax IGST RCM - GCF": 0.0} | GK36: Exempted - GCF | GL36: 0 | GO36: 80 | GP36: Amount | GS36: 11410 | GT36: 11410 | GU36: 1630 | GV36: 1630 | GW36: 0 | GX36: 7 | GY36: 1550 | GZ36: 1550 | HE36: PO/N/25-26/0032 | HF36: 4c44qpbdp6 | HG36: PR/N/25-26/0082 | HH36: 9cr4ljj2tr | HJ36: 32.6 | HK36: 0 | HL36: 0 | HM36: 0 | HN36: 7 | HP36: 0 | HT36: 0 | IA36: 0 | IB36: 0 | ID36: KGS | IE36: Noida | IF36: 11410 | IG36: 0 | IH36: 0 | II36: 32.6 | IJ36: 0 | IN36: INR | IO36: Input Tax SGST - GCF | IP36: Add | IQ36: 0 | IR36: 0 | IT36: Total | IU36: 0 | IV36: Main - GCF | IW36: Input Tax SGST @ 9.0 | IX36: sgst | IY36: 0 | IZ36: 0 | JA36: {"Maida":[0.0,0.0],"Maida Patent":[0.0,0.0],"Suji":[0.0,0.0]} | JC36: 0 | JD36: 0 | JE36: 0 | JF36: 38060 | JG36: 38060 | JH36: On Net Total
ER37: 1 | ES37: 44 | ET37: 1450 | EU37: 1450 | EV37: Suji | EW37: 1450 | EX37: 1450 | EY37: BAG | EZ37: 44 | FA37: Stores Noida - GCF | FB37: 0 | FC37: 1 | FI37: 0 | FJ37: 0 | FK37: 0 | FL37: 0 | FM37: 0 | FN37: 0 | FO37: Main - GCF | FQ37: Suji | FR37: -70 | FS37: 0 | FT37: 0 | FU37: 0 | FV37: Stock Received But Not Billed - GCF | FX37: Exempted | FY37: 110100 | FZ37: 0 | GA37: 0 | GC37: 0 | GD37: 0 | GE37: 0 | GF37: 0 | GG37: Suji | GH37: Cookies - RM | GI37: 0 | GJ37: {"Input Tax CGST - GCF": 0.0, "Input Tax SGST - GCF": 0.0, "Input Tax IGST - GCF": 0.0, "Output Tax CGST - GCF": 0.0, "Output Tax SGST - GCF": 0.0, "Output Tax IGST - GCF": 0.0, "Input Tax CGST RCM - GCF": 0.0, "Input Tax SGST RCM - GCF": 0.0, "Input Tax IGST RCM - GCF": 0.0} | GK37: Exempted - GCF | GL37: 0 | GO37: 70 | GP37: Amount | GS37: 1450 | GT37: 1450 | GU37: 1450 | GV37: 1450 | GW37: 0 | GX37: 1 | GY37: 1380 | GZ37: 1380 | HE37: PO/N/25-26/0032 | HF37: 4c4468q1v4 | HG37: PR/N/25-26/0082 | HH37: 9cr4bp1p7s | HJ37: 32.95 | HK37: 0 | HL37: 0 | HM37: 0 | HN37: 1 | HP37: 0 | HT37: 0 | IA37: 0 | IB37: 0 | ID37: KGS | IE37: Noida | IF37: 1450 | IG37: 0 | IH37: 0 | II37: 32.954545 | IJ37: 0
A38: PI/N/25-26/0034-1 | B38: PI/N/25-26/0034-1-1 | C38: PINV-.YY.- | D38: Om Mithila Industries | E38: 45850 | F38: Noida | G38: Creditors - GCF | H38: Om Mithila Industries | I38: Om Mithila Industries | L38: G. C. Foods Pvt. Ltd. | M38: 0 | N38: 1 | O38: 45850 | Q38: 0 | R38: 0 | T38: 1 | U38: 0 | V38: 1 | W38: 0 | X38: 0 | Z38: 497/25-26 | AA38: 45850 | AD38: INR | AE38: 1 | AF38: 1 | AG38: Standard Selling Delhi | AH38: INR | AI38: 1 | AJ38: 0 | AL38: 0 | AM38: Stores Noida - GCF | AO38: 0 | AR38: 1520 | AS38: 0 | AT38: 29640 | AU38: 29640 | AV38: 29640 | AW38: 29640 | AX38: 29640 | AY38: 29640 | BA38: Input GST In-state - GCF | BE38: 3557 | BF38: 0 | BG38: 3557 | BH38: 3557 | BI38: 0 | BJ38: 3557 | BK38: 33197 | BL38: 0 | BM38: 0 | BN38: INR Thirty Three Thousand, One Hundred And Ninety Seven only. | BO38: 33197 | BP38: 0 | BQ38: 0 | BR38: 0 | BS38: INR Thirty Three Thousand, One Hundred And Ninety Seven only. | BT38: 0 | BU38: 33197 | BV38: 1 | BW38: Grand Total | BX38: 0 | BY38: 0 | BZ38: 0 | CA38: | HSN/SAC | Taxable Amount | Input Tax CGST @ 9.0 | Input Tax SGST @ 9.0 | Rounded Off | | --- | --- | --- | --- | --- | | 48191010 | ₹ 29,640.00 | (6.0%) ₹ 1,778.40 | (6.0%) ₹ 1,778.40 | ₹ 0.20 | | CC38: 0 | CF38: 0 | CG38: 0 | CH38: 0 | CI38: 0 | CJ38: 0 | CM38: Om Mithila Industries-Billing | CN38: A-109 V Sec - 80 Noida, G.B NagarNoida, Uttar Pradesh, State Code: 09, Pincode: 201305, India, GSTIN: 09AOYPS4034E1ZG, | CO38: 09AOYPS4034E1ZG | CP38: Registered Regular | CU38: Om Mithila Industries-Billing | CV38: A-109 V Sec - 80 Noida, G.B NagarNoida, Uttar Pradesh, State Code: 09, Pincode: 201305, India, GSTIN: 09AOYPS4034E1ZG, | CW38: G.C. Foods Pvt. Ltd. Noida - Uttar Pradesh (Shipping) | CX38: B-64, Sector-80,, Noida, Gautam Buddha Nagar, Noida, Uttar Pradesh, State Code: 09, Pincode: 201305, India, Phone: 9958003759, GSTIN: 09AACCG2244H1ZS, | CY38: G.C. Foods Pvt. Ltd. Noida - Uttar Pradesh (Shipping) | CZ38: B-64, Sector-80,, Noida, Gautam Buddha Nagar, Noida, Uttar Pradesh, State Code: 09, Pincode: 201305, India, Phone: 9958003759, GSTIN: 09AACCG2244H1ZS, | DA38: 09AACCG2244H1ZS | DB38: 09-Uttar Pradesh | DD38: 0 | DF38: Ingate No-137, Invoice Bo 497/25-26, Invoice date-12/7/25, Ingate Date -12/7/25 | DG38: 100 | DH38: INR | DI38: No | DJ38: Stock Received But Not Billed - GCF | DP38: GCF Letterhead | DQ38: 0 | DS38: en | DY38: 0 | EA38: Road | EC38: 45859 | ED38: Regular | EE38: All Other ITC | EG38: Unreconciled | EH38: 0 | EK38: 0 | EM38: Creditors - Raw Material | EO38: 0 | EP38: Against Supplier Invoice 497/25-26 dated 12-07-2025 | ER38: 1520 | ES38: 1520 | ET38: 29640 | EU38: 29640 | EV38: Carton - Suji Rusk 65g | EW38: 19.5 | EX38: 19.5 | EY38: PCS | EZ38: 1 | FA38: Stores Noida - GCF | FB38: 0 | FC38: 1 | FI38: 0 | FJ38: 0 | FK38: 0 | FL38: 0 | FM38: 1778.4 | FN38: 6 | FO38: Main - GCF | FQ38: Carton Box - Suji Rusk 65 Gm | FR38: 0 | FS38: 0 | FT38: 0 | FU38: 0 | FV38: Stock Received But Not Billed - GCF | FX38: Taxable | FY38: 48191010 | FZ38: 0 | GA38: 0 | GC38: 0 | GD38: 0 | GE38: 0 | GF38: 0 | GG38: Carton - Suji Rusk 65g | GH38: Cookies - PM | GI38: 0 | GJ38: {"Output Tax SGST - GCF": 6.0, "Output Tax CGST - GCF": 6.0, "Output Tax IGST - GCF": 12.0, "Input Tax SGST - GCF": 6.0, "Input Tax CGST - GCF": 6.0, "Input Tax IGST - GCF": 12.0, "Input Tax SGST RCM - GCF": 6.0, "Input Tax CGST RCM - GCF": 6.0, "Input Tax IGST RCM - GCF": 12.0} | GK38: GST 12% - GCF | GL38: 0 | GO38: 0 | GS38: 29640 | GT38: 29640 | GU38: 19.5 | GV38: 19.5 | GW38: 0 | GX38: 1520 | GY38: 19.5 | GZ38: 19.5 | HG38: PR/N/25-26/0074 | HH38: 8rmo4ojobu | HJ38: 19.5 | HK38: 0 | HL38: 0 | HM38: 0 | HN38: 1520 | HP38: 0 | HT38: 0 | IA38: 1778.4 | IB38: 6 | ID38: PCS | IE38: Noida | IF38: 29640 | IG38: 0 | IH38: 0 | II38: 19.5 | IJ38: 0 | IN38: INR | IO38: Input Tax CGST - GCF | IP38: Add | IQ38: 1778.4 | IR38: 1778.4 | IT38: Total | IU38: 0 | IV38: Main - GCF | IW38: Input Tax CGST @ 9.0 | IX38: cgst | IY38: 0 | IZ38: 0 | JA38: {"Carton - Suji Rusk 65g":[6.0,1778.4]} | JC38: 1778.4 | JD38: 1778.4 | JE38: 0 | JF38: 31418.4 | JG38: 31418.4 | JH38: On Net Total | LD38: 0 | LF38: Percentage | LG38: 0 | LH38: 45850 | LI38: 100 | LK38: 33197 | LL38: 33197 | LM38: 0 | LN38: 0 | LO38: 33197 | LP38: 33197
IN39: INR | IO39: Input Tax SGST - GCF | IP39: Add | IQ39: 1778.4 | IR39: 1778.4 | IT39: Total | IU39: 0 | IV39: Main - GCF | IW39: Input Tax SGST @ 9.0 | IX39: sgst | IY39: 0 | IZ39: 0 | JA39: {"Carton - Suji Rusk 65g":[6.0,1778.4]} | JC39: 1778.4 | JD39: 1778.4 | JE39: 0 | JF39: 33196.8 | JG39: 33196.8 | JH39: On Net Total
